Workbook

Sheet Samdat
A1: Sample name: | B1: ENTER SAMPLE NAME HERE
A2: **paste sample data below** | E2: Benchling Copyable Table | L2: Benchling Copyable Table
E3: Material | F3: Element | G3: Concentration (ppm) | H3: Signal Quality | I3: LOD (ppm) | L3: Material | M3: Element | N3: Signal Intensity
D4: =SUBSTITUTE(SUBSTITUTE(TRIM(RIGHT(F4,4)),")",""),"(","") -> K | E4: =$B$1 -> ENTER SAMPLE NAME HERE | F4: Potassium (K) | G4: {=INDIRECT(""&D4&"!B3")} -> — | H4: {=INDIRECT(""&D4&"!B4")} -> No Signal | I4: =VLOOKUP(D4,Caldat!$W$2:$Y$38,2,FALSE) -> 15 | K4: =SUBSTITUTE(SUBSTITUTE(TRIM(RIGHT(M4,4)),")",""),"(","") -> Ca | L4: =$B$1 -> ENTER SAMPLE NAME HERE | M4: Calcium (Ca) | N4: =IFERROR(VLOOKUP(K4,$A$4:$B$100,2,FALSE),0) -> 0
D5: =SUBSTITUTE(SUBSTITUTE(TRIM(RIGHT(F5,4)),")",""),"(","") -> Ca | E5: =$B$1 -> ENTER SAMPLE NAME HERE | F5: Calcium (Ca) | G5: {=INDIRECT(""&D5&"!B3")} -> — | H5: {=INDIRECT(""&D5&"!B4")} -> No Signal | I5: =VLOOKUP(D5,Caldat!$W$2:$Y$38,2,FALSE) -> 15 | K5: =SUBSTITUTE(SUBSTITUTE(TRIM(RIGHT(M5,4)),")",""),"(","") -> K | L5: =$B$1 -> ENTER SAMPLE NAME HERE | M5: Potassium (K) | N5: =IFERROR(VLOOKUP(K5,$A$4:$B$100,2,FALSE),0) -> 0
D6: =SUBSTITUTE(SUBSTITUTE(TRIM(RIGHT(F6,4)),")",""),"(","") -> Cr | E6: =$B$1 -> ENTER SAMPLE NAME HERE | F6: Chromium (Cr) | G6: {=INDIRECT(""&D6&"!B3")} -> — | H6: {=INDIRECT(""&D6&"!B4")} -> No Signal | I6: =VLOOKUP(D6,Caldat!$W$2:$Y$38,2,FALSE) -> 8 | K6: =SUBSTITUTE(SUBSTITUTE(TRIM(RIGHT(M6,4)),")",""),"(","") -> Cl | L6: =$B$1 -> ENTER SAMPLE NAME HERE | M6: Chlorine (Cl) | N6: =IFERROR(VLOOKUP(K6,$A$4:$B$100,2,FALSE),0) -> 0
D7: =SUBSTITUTE(SUBSTITUTE(TRIM(RIGHT(F7,4)),")",""),"(","") -> Mn | E7: =$B$1 -> ENTER SAMPLE NAME HERE | F7: Manganese (Mn) | G7: {=INDIRECT(""&D7&"!B3")} -> — | H7: {=INDIRECT(""&D7&"!B4")} -> No Signal | I7: =VLOOKUP(D7,Caldat!$W$2:$Y$38,2,FALSE) -> 6 | K7: =SUBSTITUTE(SUBSTITUTE(TRIM(RIGHT(M7,4)),")",""),"(","") -> Mn | L7: =$B$1 -> ENTER SAMPLE NAME HERE | M7: Manganese (Mn) | N7: =IFERROR(VLOOKUP(K7,$A$4:$B$100,2,FALSE),0) -> 0
D8: =SUBSTITUTE(SUBSTITUTE(TRIM(RIGHT(F8,4)),")",""),"(","") -> Fe | E8: =$B$1 -> ENTER SAMPLE NAME HERE | F8: Iron (Fe) | G8: {=INDIRECT(""&D8&"!B3")} -> — | H8: {=INDIRECT(""&D8&"!B4")} -> No Signal | I8: =VLOOKUP(D8,Caldat!$W$2:$Y$38,2,FALSE) -> 5 | K8: =SUBSTITUTE(SUBSTITUTE(TRIM(RIGHT(M8,4)),")",""),"(","") -> Fe | L8: =$B$1 -> ENTER SAMPLE NAME HERE | M8: Iron (Fe) | N8: =IFERROR(VLOOKUP(K8,$A$4:$B$100,2,FALSE),0) -> 0
D9: =SUBSTITUTE(SUBSTITUTE(TRIM(RIGHT(F9,4)),")",""),"(","") -> Ni | E9: =$B$1 -> ENTER SAMPLE NAME HERE | F9: Nickel (Ni) | G9: {=INDIRECT(""&D9&"!B3")} -> — | H9: {=INDIRECT(""&D9&"!B4")} -> No Signal | I9: =VLOOKUP(D9,Caldat!$W$2:$Y$38,2,FALSE) -> 4 | K9: =SUBSTITUTE(SUBSTITUTE(TRIM(RIGHT(M9,4)),")",""),"(","") -> Si | L9: =$B$1 -> ENTER SAMPLE NAME HERE | M9: Silicon (Si) | N9: =IFERROR(VLOOKUP(K9,$A$4:$B$100,2,FALSE),0) -> 0
D10: =SUBSTITUTE(SUBSTITUTE(TRIM(RIGHT(F10,4)),")",""),"(","") -> Cu | E10: =$B$1 -> ENTER SAMPLE NAME HERE | F10: Copper (Cu) | G10: {=INDIRECT(""&D10&"!B3")} -> — | H10: {=INDIRECT(""&D10&"!B4")} -> No Signal | I10: =VLOOKUP(D10,Caldat!$W$2:$Y$38,2,FALSE) -> 4 | K10: =SUBSTITUTE(SUBSTITUTE(TRIM(RIGHT(M10,4)),")",""),"(","") -> Sr | L10: =$B$1 -> ENTER SAMPLE NAME HERE | M10: Strontium (Sr) | N10: =IFERROR(VLOOKUP(K10,$A$4:$B$100,2,FALSE),0) -> 0
D11: =SUBSTITUTE(SUBSTITUTE(TRIM(RIGHT(F11,4)),")",""),"(","") -> Zn | E11: =$B$1 -> ENTER SAMPLE NAME HERE | F11: Zinc (Zn) | G11: {=INDIRECT(""&D11&"!B3")} -> — | H11: {=INDIRECT(""&D11&"!B4")} -> No Signal | I11: =VLOOKUP(D11,Caldat!$W$2:$Y$38,2,FALSE) -> 5 | K11: =SUBSTITUTE(SUBSTITUTE(TRIM(RIGHT(M11,4)),")",""),"(","") -> S | L11: =$B$1 -> ENTER SAMPLE NAME HERE | M11: Sulfur (S) | N11: =IFERROR(VLOOKUP(K11,$A$4:$B$100,2,FALSE),0) -> 0
D12: =SUBSTITUTE(SUBSTITUTE(TRIM(RIGHT(F12,4)),")",""),"(","") -> Sr | E12: =$B$1 -> ENTER SAMPLE NAME HERE | F12: Strontium (Sr) | G12: {=INDIRECT(""&D12&"!B3")} -> — | H12: {=INDIRECT(""&D12&"!B4")} -> No Signal | I12: =VLOOKUP(D12,Caldat!$W$2:$Y$38,2,FALSE) -> 3 | K12: =SUBSTITUTE(SUBSTITUTE(TRIM(RIGHT(M12,4)),")",""),"(","") -> Ti | L12: =$B$1 -> ENTER SAMPLE NAME HERE | M12: Titanium (Ti) | N12: =IFERROR(VLOOKUP(K12,$A$4:$B$100,2,FALSE),0) -> 0
D13: =SUBSTITUTE(SUBSTITUTE(TRIM(RIGHT(F13,4)),")",""),"(","") -> Mo | E13: =$B$1 -> ENTER SAMPLE NAME HERE | F13: Molybdenum (Mo) | G13: {=INDIRECT(""&D13&"!B3")} -> — | H13: {=INDIRECT(""&D13&"!B4")} -> No Signal | I13: =VLOOKUP(D13,Caldat!$W$2:$Y$38,2,FALSE) -> 3 | K13: =SUBSTITUTE(SUBSTITUTE(TRIM(RIGHT(M13,4)),")",""),"(","") -> Cu | L13: =$B$1 -> ENTER SAMPLE NAME HERE | M13: Copper (Cu) | N13: =IFERROR(VLOOKUP(K13,$A$4:$B$100,2,FALSE),0) -> 0
D14: =SUBSTITUTE(SUBSTITUTE(TRIM(RIGHT(F14,4)),")",""),"(","") -> Pb | E14: =$B$1 -> ENTER SAMPLE NAME HERE | F14: Lead (Pb) | G14: {=INDIRECT(""&D14&"!B3")} -> — | H14: {=INDIRECT(""&D14&"!B4")} -> No Signal | I14: =VLOOKUP(D14,Caldat!$W$2:$Y$38,2,FALSE) -> 10 | K14: =SUBSTITUTE(SUBSTITUTE(TRIM(RIGHT(M14,4)),")",""),"(","") -> Zn | L14: =$B$1 -> ENTER SAMPLE NAME HERE | M14: Zinc (Zn) | N14: =IFERROR(VLOOKUP(K14,$A$4:$B$100,2,FALSE),0) -> 0
D15: =SUBSTITUTE(SUBSTITUTE(TRIM(RIGHT(F15,4)),")",""),"(","") -> Co | E15: =$B$1 -> ENTER SAMPLE NAME HERE | F15: Cobalt (Co) | G15: {=INDIRECT(""&D15&"!B3")} -> — | H15: {=INDIRECT(""&D15&"!B4")} -> No Signal | I15: =VLOOKUP(D15,Caldat!$W$2:$Y$38,2,FALSE) -> 5 | K15: =SUBSTITUTE(SUBSTITUTE(TRIM(RIGHT(M15,4)),")",""),"(","") -> Te | L15: =$B$1 -> ENTER SAMPLE NAME HERE | M15: Tellurium (Te) | N15: =IFERROR(VLOOKUP(K15,$A$4:$B$100,2,FALSE),0) -> 0
... D21: =SUBSTITUTE(SUBSTITUTE(TRIM(RIGHT(F21,4)),")",""),"(","") -> Tl | E21: =$B$1 -> ENTER SAMPLE NAME HERE | F21: Thallium (Tl) | G21: {=INDIRECT(""&D21&"!B3")} -> — | H21: {=INDIRECT(""&D21&"!B4")} -> No Signal | I21: =VLOOKUP(D21,Caldat!$W$2:$Y$38,2,FALSE) -> 10 | K21: =SUBSTITUTE(SUBSTITUTE(TRIM(RIGHT(M21,4)),")",""),"(","") -> P | L21: =$B$1 -> ENTER SAMPLE NAME HERE | M21: Phosphorus (P) | N21: =IFERROR(VLOOKUP(K21,$A$4:$B$100,2,FALSE),0) -> 0
K22: =SUBSTITUTE(SUBSTITUTE(TRIM(RIGHT(M22,4)),")",""),"(","") -> Ni | L22: =$B$1 -> ENTER SAMPLE NAME HERE | M22: Nickel (Ni) | N22: =IFERROR(VLOOKUP(K22,$A$4:$B$100,2,FALSE),0) -> 0
K23: =SUBSTITUTE(SUBSTITUTE(TRIM(RIGHT(M23,4)),")",""),"(","") -> V | L23: =$B$1 -> ENTER SAMPLE NAME HERE | M23: Vanadium (V) | N23: =IFERROR(VLOOKUP(K23,$A$4:$B$100,2,FALSE),0) -> 0
K24: =SUBSTITUTE(SUBSTITUTE(TRIM(RIGHT(M24,4)),")",""),"(","") -> Y | L24: =$B$1 -> ENTER SAMPLE NAME HERE | M24: Yttrium (Y) | N24: =IFERROR(VLOOKUP(K24,$A$4:$B$100,2,FALSE),0) -> 0
K25: =SUBSTITUTE(SUBSTITUTE(TRIM(RIGHT(M25,4)),")",""),"(","") -> Mo | L25: =$B$1 -> ENTER SAMPLE NAME HERE | M25: Molybdenum (Mo) | N25: =IFERROR(VLOOKUP(K25,$A$4:$B$100,2,FALSE),0) -> 0
K26: =SUBSTITUTE(SUBSTITUTE(TRIM(RIGHT(M26,4)),")",""),"(","") -> W | L26: =$B$1 -> ENTER SAMPLE NAME HERE | M26: Tungsten (W) | N26: =IFERROR(VLOOKUP(K26,$A$4:$B$100,2,FALSE),0) -> 0
K27: =SUBSTITUTE(SUBSTITUTE(TRIM(RIGHT(M27,4)),")",""),"(","") -> As | L27: =$B$1 -> ENTER SAMPLE NAME HERE | M27: Arsenic (As) | N27: =IFERROR(VLOOKUP(K27,$A$4:$B$100,2,FALSE),0) -> 0
K28: =SUBSTITUTE(SUBSTITUTE(TRIM(RIGHT(M28,4)),")",""),"(","") -> Bi | L28: =$B$1 -> ENTER SAMPLE NAME HERE | M28: Bismuth (Bi) | N28: =IFERROR(VLOOKUP(K28,$A$4:$B$100,2,FALSE),0) -> 0
K29: =SUBSTITUTE(SUBSTITUTE(TRIM(RIGHT(M29,4)),")",""),"(","") -> Cd | L29: =$B$1 -> ENTER SAMPLE NAME HERE | M29: Cadmium (Cd) | N29: =IFERROR(VLOOKUP(K29,$A$4:$B$100,2,FALSE),0) -> 0
K30: =SUBSTITUTE(SUBSTITUTE(TRIM(RIGHT(M30,4)),")",""),"(","") -> Co | L30: =$B$1 -> ENTER SAMPLE NAME HERE | M30: Cobalt (Co) | N30: =IFERROR(VLOOKUP(K30,$A$4:$B$100,2,FALSE),0) -> 0
K31: =SUBSTITUTE(SUBSTITUTE(TRIM(RIGHT(M31,4)),")",""),"(","") -> Ga | L31: =$B$1 -> ENTER SAMPLE NAME HERE | M31: Gallium (Ga) | N31: =IFERROR(VLOOKUP(K31,$A$4:$B$100,2,FALSE),0) -> 0
K32: =SUBSTITUTE(SUBSTITUTE(TRIM(RIGHT(M32,4)),")",""),"(","") -> Ir | L32: =$B$1 -> ENTER SAMPLE NAME HERE | M32: Iridium (Ir) | N32: =IFERROR(VLOOKUP(K32,$A$4:$B$100,2,FALSE),0) -> 0
K33: =SUBSTITUTE(SUBSTITUTE(TRIM(RIGHT(M33,4)),")",""),"(","") -> Pb | L33: =$B$1 -> ENTER SAMPLE NAME HERE | M33: Lead (Pb) | N33: =IFERROR(VLOOKUP(K33,$A$4:$B$100,2,FALSE),0) -> 0
... K35: =SUBSTITUTE(SUBSTITUTE(TRIM(RIGHT(M35,4)),")",""),"(","") -> Cs | L35: =$B$1 -> ENTER SAMPLE NAME HERE | M35: Cesium (Cs) | N35: =IFERROR(VLOOKUP(K35,$A$4:$B$100,2,FALSE),0) -> 0

Sheet Caldat
A1: YP50-0 | D1: YP50-1 | G1: YP50-2 | J1: YP50-3 | M1: YP50-4 | P1: YP50-5 | S1: YP50-6 | W1: Lower Limits | AC1: K | AD1: Ca | AE1: V | AF1: Cr | AG1: Mn | AH1: Fe | AI1: Co | AJ1: Ni | AK1: Cu | AL1: Zn | AM1: Ga | AN1: Rb | AO1: Sr | AP1: Mo | AQ1: Cd | AR1: Tl | AS1: Pb | AT1: Bi
A2: S | C2: ppm | D2: S | F2: ppm | G2: S | I2: ppm | J2: S | L2: ppm | M2: S | O2: ppm | P2: S | R2: ppm | S2: S | U2: ppm | W2: K | X2: 15 | Y2: ppm | AA2: True Concentrations (ppm) | AB2: YP50-0 | AC2: 125.146 | AD2: 206.2861 | AE2: 0 | AF2: 6.4965 | AG2: 0 | AH2: 34.79 | AI2: 0 | AJ2: 0.461 | AK2: 20.54 | AL2: 0 | AM2: 0 | AN2: 0 | AO2: 0 | AP2: 0 | AQ2: 0 | AR2: 0 | AS2: 0 | AT2: 0
A3: Cl | C3: ppm | D3: Cl | F3: ppm | G3: Cl | I3: ppm | J3: Cl | L3: ppm | M3: Cl | O3: ppm | P3: Cl | R3: ppm | S3: Cl | U3: ppm | W3: Ca | X3: 15 | Y3: ppm | AB3: YP50-1 | AC3: 225.866 | AD3: 307.00591 | AE3: 10.07198 | AF3: 16.56848 | AG3: 10.07198 | AH3: 135.5098 | AI3: 10.071981 | AJ3: 10.53298 | AK3: 30.61198 | AL3: 10.07198 | AM3: 10.07198 | AN3: 10.07198 | AO3: 10.07198 | AP3: 10.07198 | AQ3: 10.07198 | AR3: 10.07198 | AS3: 10.07198 | AT3: 10.071981
A4: K | C4: ppm | D4: K | F4: ppm | G4: K | I4: ppm | J4: K | L4: ppm | M4: K | O4: ppm | P4: K | R4: ppm | S4: K | U4: ppm | W4: V | X4: 10 | Y4: ppm | AB4: YP50-2 | AC4: 308.777 | AD4: 389.91667 | AE4: 18.36306 | AF4: 24.85956 | AG4: 18.36306 | AH4: 218.4206 | AI4: 18.363056 | AJ4: 18.82406 | AK4: 38.90306 | AL4: 18.36306 | AM4: 18.36306 | AN4: 18.36306 | AO4: 18.36306 | AP4: 18.36306 | AQ4: 18.36306 | AR4: 18.36306 | AS4: 18.36306 | AT4: 18.363056
A5: Ca | C5: ppm | D5: Ca | F5: ppm | G5: Ca | I5: ppm | J5: Ca | L5: ppm | M5: Ca | O5: ppm | P5: Ca | R5: ppm | S5: Ca | U5: ppm | W5: Cr | X5: 8 | Y5: ppm | AB5: YP50-3 | AC5: 491.25 | AD5: 572.3897 | AE5: 36.61036 | AF5: 43.10686 | AG5: 36.61036 | AH5: 400.8936 | AI5: 36.61036 | AJ5: 37.07136 | AK5: 57.15036 | AL5: 36.61036 | AM5: 36.61036 | AN5: 36.61036 | AO5: 36.61036 | AP5: 36.61036 | AQ5: 36.61036 | AR5: 36.61036 | AS5: 36.61036 | AT5: 36.61036
A6: Cr | C6: ppm | D6: Cr | F6: ppm | G6: Cr | I6: ppm | J6: Cr | L6: ppm | M6: Cr | O6: ppm | P6: Cr | R6: ppm | S6: Cr | U6: ppm | W6: Mn | X6: 6 | Y6: ppm | AB6: YP50-4 | AC6: 860.159 | AD6: 941.29921 | AE6: 73.50131 | AF6: 79.99781 | AG6: 73.50131 | AH6: 769.8031 | AI6: 73.501311 | AJ6: 73.96231 | AK6: 94.04131 | AL6: 73.50131 | AM6: 73.50131 | AN6: 73.50131 | AO6: 73.50131 | AP6: 73.50131 | AQ6: 73.50131 | AR6: 73.50131 | AS6: 73.50131 | AT6: 73.501311
A7: Fe | C7: ppm | D7: Fe | F7: ppm | G7: Fe | I7: ppm | J7: Fe | L7: ppm | M7: Fe | O7: ppm | P7: Fe | R7: ppm | S7: Fe | U7: ppm | W7: Fe | X7: 5 | Y7: ppm | AB7: YP50-5 | AC7: 1214.036 | AD7: 1295.1764 | AE7: 108.889 | AF7: 115.3855 | AG7: 108.889 | AH7: 1123.68 | AI7: 108.88903 | AJ7: 109.35 | AK7: 129.429 | AL7: 108.889 | AM7: 108.889 | AN7: 108.889 | AO7: 108.889 | AP7: 108.889 | AQ7: 108.889 | AR7: 108.889 | AS7: 108.889 | AT7: 108.88903
A8: Ni | C8: ppm | D8: Ni | F8: ppm | G8: Ni | I8: ppm | J8: Ni | L8: ppm | M8: Ni | O8: ppm | P8: Ni | R8: ppm | S8: Ni | U8: ppm | W8: Co | X8: 5 | Y8: ppm | AB8: YP50-6 | AC8: 1578.199 | AD8: 1659.3394 | AE8: 145.3053 | AF8: 151.8018 | AG8: 145.3053 | AH8: 1487.843 | AI8: 145.30533 | AJ8: 145.7663 | AK8: 165.8453 | AL8: 145.3053 | AM8: 145.3053 | AN8: 145.3053 | AO8: 145.3053 | AP8: 145.3053 | AQ8: 145.3053 | AR8: 145.3053 | AS8: 145.3053 | AT8: 145.30533
A9: Cu | C9: ppm | D9: Cu | F9: ppm | G9: Cu | I9: ppm | J9: Cu | L9: ppm | M9: Cu | O9: ppm | P9: Cu | R9: ppm | S9: Cu | U9: ppm | W9: Ni | X9: 4 | Y9: ppm
A10: Sn | C10: ppm | D10: Sn | F10: ppm | G10: Sn | I10: ppm | J10: Os | L10: ppm | M10: Sn | O10: ppm | P10: Sn | R10: ppm | S10: Sn | U10: ppm | W10: Cu | X10: 4 | Y10: ppm
A11: Os | C11: ppm | D11: Os | F11: ppm | G11: Os | I11: ppm | J11: Si | L11: ppm | M11: Os | O11: ppm | P11: Os | R11: ppm | S11: Os | U11: ppm | W11: Zn | X11: 5 | Y11: ppm
A12: Si | C12: ppm | D12: Si | F12: ppm | G12: Si | I12: ppm | J12: P | L12: ppm | M12: Si | O12: ppm | P12: Si | R12: ppm | S12: Si | U12: ppm | W12: Ga | X12: 5 | Y12: ppm
A13: P | C13: ppm | D13: P | F13: ppm | G13: P | I13: ppm | J13: Ti | L13: ppm | M13: P | O13: ppm | P13: P | R13: ppm | S13: P | U13: ppm | W13: Rb | X13: 4 | Y13: ppm
D14: Ti | F14: ppm | G14: Ti | I14: ppm | J14: V | L14: ppm | M14: Ti | O14: ppm | P14: Ti | R14: ppm | S14: V | U14: ppm | W14: Sr | X14: 3 | Y14: ppm
D15: V | F15: ppm | G15: V | I15: ppm | J15: Mn | L15: ppm | M15: V | O15: ppm | P15: V | R15: ppm | S15: Mn | U15: ppm | W15: Mo | X15: 3 | Y15: ppm
D16: Mn | F16: ppm | G16: Mn | I16: ppm | J16: Co | L16: ppm | M16: Mn | O16: ppm | P16: Mn | R16: ppm | S16: Co | U16: ppm | W16: Cd | X16: 15 | Y16: ppm
D17: Co | F17: ppm | G17: Co | I17: ppm | J17: Zn | L17: ppm | M17: Co | O17: ppm | P17: Co | R17: ppm | S17: Zn | U17: ppm | W17: Tl | X17: 10 | Y17: ppm
D18: Zn | F18: ppm | G18: Zn | I18: ppm | J18: Ga | L18: ppm | M18: Zn | O18: ppm | P18: Zn | R18: ppm | S18: Ga | U18: ppm | W18: Pb | X18: 10 | Y18: ppm
D19: Ga | F19: ppm | G19: Ga | I19: ppm | J19: As | L19: ppm | M19: Ga | O19: ppm | P19: Ga | R19: ppm | S19: As | U19: ppm | W19: Bi | X19: 10 | Y19: ppm
D20: As | F20: ppm | G20: As | I20: ppm | J20: Rb | L20: ppm | M20: As | O20: ppm | P20: As | R20: ppm | S20: Rb | U20: ppm
D21: Rb | F21: ppm | G21: Rb | I21: ppm | J21: Sr | L21: ppm | M21: Rb | O21: ppm | P21: Rb | R21: ppm | S21: Sr | U21: ppm
D22: Sr | F22: ppm | G22: Sr | I22: ppm | J22: Zr | L22: ppm | M22: Sr | O22: ppm | P22: Sr | R22: ppm | S22: Zr | U22: ppm
D23: Zr | F23: ppm | G23: Zr | I23: ppm | J23: Er | L23: ppm | M23: Zr | O23: ppm | P23: Zr | R23: ppm | S23: Tl | U23: ppm
D24: Er | F24: ppm | G24: Er | I24: ppm | J24: Tl | L24: ppm | M24: Er | O24: ppm | P24: Tl | R24: ppm | S24: Pb | U24: ppm
D25: Yb | F25: ppm | G25: Re | I25: ppm | J25: Pb | L25: ppm | M25: Tl | O25: ppm | P25: Pb | R25: ppm | S25: Bi | U25: ppm
D26: Re | F26: ppm | G26: Tl | I26: ppm | J26: Bi | L26: ppm | M26: Pb | O26: ppm | P26: Bi | R26: ppm | S26: Th | U26: ppm
D27: Tl | F27: ppm | G27: Pb | I27: ppm | J27: Th | L27: ppm | M27: Bi | O27: ppm | P27: Th | R27: ppm | S27: Y | U27: ppm
D28: Pb | F28: ppm | G28: Bi | I28: ppm | J28: Y | L28: ppm | M28: Th | O28: ppm | P28: Y | R28: ppm | S28: Mo | U28: ppm
D29: Bi | F29: ppm | G29: Th | I29: ppm | J29: Mo | L29: ppm | M29: Y | O29: ppm | P29: Mo | R29: ppm | S29: Cd | U29: ppm
D30: Th | F30: ppm | G30: Y | I30: ppm | J30: Cd | L30: ppm | M30: Mo | O30: ppm | P30: Cd | R30: ppm | S30: In | U30: ppm
G31: Mo | I31: ppm | J31: In | L31: ppm | M31: Cd | O31: ppm | P31: In | R31: ppm | S31: Ir | U31: ppm
I32: ppm | J32: Ir | L32: ppm | M32: In | O32: ppm | P32: Ir | R32: ppm | S32: La
L33: ppm | M33: Ir | O33: ppm | P33: La | R33: ppm | S33: Br
M34: La

Sheet K
A1: Element | B1: Potassium | E1: Range | F1: Sample | G1: =""&$B$2&" ppm" -> K ppm | H1: =""&$B$2&" Signal" -> K Signal | K1: Range 1: | L1: Range Min Signal | M1: {=INDIRECT("H"&(MATCH(1,E2:E8,0)+1)&"")} -> 0 | P1: Range 2: | Q1: Range Min Signal | R1: {=INDIRECT("H"&(MATCH(2,E2:E8,0)+1)&"")} -> 0
B2: K | D2: Range 1 | E2: 1 | F2: YP50-0 | G2: =HLOOKUP($B$2,Caldat!$AC$1:$AT$8,ROW(F2),FALSE) -> 125.146 | H2: =IFERROR(VLOOKUP($B$2,Caldat!A$2:C$38,2,FALSE),0) -> 0 | L2: Range Max Signal | M2: {=INDIRECT("H"&(MATCH(1,E2:E8,1)+1)&"")} -> 0 | Q2: Range Max Signal | R2: {=INDIRECT("H"&(MATCH(2,E2:E8,1)+1)&"")} -> 0
A3: Concentration (ppm) | B3: =IF(M7<B5,"—",IF(M3<M2,M7,IF(M3<R1,((M3-M2)/(R1-M2))*R7+(1-((M3-M2)/(R1-M2)))*M7,R7))) -> — | E3: 1 | F3: YP50-1 | G3: =HLOOKUP($B$2,Caldat!$AC$1:$AT$8,ROW(F3),FALSE) -> 225.866 | H3: =VLOOKUP($B$2,Caldat!D$2:F$38,2,FALSE) -> 0 | L3: y (signal from sample) | M3: =IFERROR(VLOOKUP($B$2,Samdat!$A$4:$B$50,2,FALSE),"—") -> — | Q3: y (signal from sample) | R3: =M3 -> —
A4: Signal Quality | B4: =IF(M7<B5,"Not Significant",IF(M3<M1,"Low Signal",IF(M3<M2,"In Range",IF(M3<R2,"In Range",IF(M3<>"—","High Signal","No Signal"))))) -> No Signal | E4: 1 | F4: YP50-2 | G4: =HLOOKUP($B$2,Caldat!$AC$1:$AT$8,ROW(F4),FALSE) -> 308.777 | H4: =VLOOKUP($B$2,Caldat!G$2:I$36,2,FALSE) -> 0 | L4: m (slope from calib. curve) | M4: =SLOPE(INDIRECT("H"&(MATCH(1,E2:E8,0)+1)&":H"&(MATCH(1,E2:E8,1)+1)&""),INDIRECT("G"&(MATCH(1,E2:E8,0)+1)&":G"&(MATCH(1,E2:E8,1)+1)&"")) -> 0 | Q4: m (slope from calib. curve) | R4: =SLOPE(INDIRECT("H"&(MATCH(2,E2:E8,0)+1)&":H"&(MATCH(2,E2:E8,1)+1)&""),INDIRECT("G"&(MATCH(2,E2:E8,0)+1)&":G"&(MATCH(2,E2:E8,1)+1)&"")) -> 0
A5: Limit of Detection (ppm) | B5: =VLOOKUP(B2,Caldat!$W$2:$Y$38,2,FALSE) -> 15 | E5: 1 | F5: YP50-3 | G5: =HLOOKUP($B$2,Caldat!$AC$1:$AT$8,ROW(F5),FALSE) -> 491.25 | H5: =VLOOKUP($B$2,Caldat!J$2:L$34,2,FALSE) -> 0 | L5: b (intercept) | M5: =INTERCEPT(INDIRECT("H"&(MATCH(1,E2:E8,0)+1)&":H"&(MATCH(1,E2:E8,1)+1)&""),INDIRECT("G"&(MATCH(1,E2:E8,0)+1)&":G"&(MATCH(1,E2:E8,1)+1)&"")) -> 0 | Q5: b (intercept) | R5: =INTERCEPT(INDIRECT("H"&(MATCH(2,E2:E8,0)+1)&":H"&(MATCH(2,E2:E8,1)+1)&""),INDIRECT("G"&(MATCH(2,E2:E8,0)+1)&":G"&(MATCH(2,E2:E8,1)+1)&"")) -> 0
A6: Std. Dev. (LOD/3) | B6: =ROUND(B5/3,2) -> 5 | D6: Range 2 | E6: 2 | F6: YP50-4 | G6: =HLOOKUP($B$2,Caldat!$AC$1:$AT$8,ROW(F6),FALSE) -> 860.159 | H6: =VLOOKUP($B$2,Caldat!M$2:O$36,2,FALSE) -> 0 | L6: R2 (fit value) | M6: =RSQ(INDIRECT("H"&(MATCH(1,E2:E8,0)+1)&":H"&(MATCH(1,E2:E8,1)+1)&""),INDIRECT("G"&(MATCH(1,E2:E8,0)+1)&":G"&(MATCH(1,E2:E8,1)+1)&"")) -> #DIV/0! | Q6: R2 (fit value) | R6: =RSQ(INDIRECT("H"&(MATCH(2,E2:E8,0)+1)&":H"&(MATCH(2,E2:E8,1)+1)&""),INDIRECT("G"&(MATCH(2,E2:E8,0)+1)&":G"&(MATCH(2,E2:E8,1)+1)&"")) -> #DIV/0!
E7: 2 | F7: YP50-5 | G7: =HLOOKUP($B$2,Caldat!$AC$1:$AT$8,ROW(F7),FALSE) -> 1214.036 | H7: =VLOOKUP($B$2,Caldat!P$2:R$32,2,FALSE) -> 0 | L7: x (concentration) | M7: =IFERROR((M3-M5)/M4,"—") -> — | Q7: x (concentration) | R7: =IFERROR((R3-R5)/R4,"—") -> —
E8: 2 | F8: YP50-6 | G8: =HLOOKUP($B$2,Caldat!$AC$1:$AT$8,ROW(F8),FALSE) -> 1578.199 | H8: =VLOOKUP($B$2,Caldat!S$2:U$29,2,FALSE) -> 0

Sheet Ca
A1: Element | B1: Calcium | E1: Range | F1: Sample | G1: =""&$B$2&" ppm" -> Ca ppm | H1: =""&$B$2&" Signal" -> Ca Signal | K1: Range 1: | L1: Range Min Signal | M1: {=INDIRECT("H"&(MATCH(1,E2:E8,0)+1)&"")} -> 0 | P1: Range 2: | Q1: Range Min Signal | R1: {=INDIRECT("H"&(MATCH(2,E2:E8,0)+1)&"")} -> 0
B2: Ca | D2: Range 1 | E2: 1 | F2: YP50-0 | G2: =HLOOKUP($B$2,Caldat!$AC$1:$AT$8,ROW(F2),FALSE) -> 206.2861 | H2: =IFERROR(VLOOKUP($B$2,Caldat!A$2:C$38,2,FALSE),0) -> 0 | L2: Range Max Signal | M2: {=INDIRECT("H"&(MATCH(1,E2:E8,1)+1)&"")} -> 0 | Q2: Range Max Signal | R2: {=INDIRECT("H"&(MATCH(2,E2:E8,1)+1)&"")} -> 0
A3: Concentration (ppm) | B3: =IF(M7<B5,"—",IF(M3<M2,M7,IF(M3<R1,((M3-M2)/(R1-M2))*R7+(1-((M3-M2)/(R1-M2)))*M7,R7))) -> — | E3: 1 | F3: YP50-1 | G3: =HLOOKUP($B$2,Caldat!$AC$1:$AT$8,ROW(F3),FALSE) -> 307.00591 | H3: =VLOOKUP($B$2,Caldat!D$2:F$38,2,FALSE) -> 0 | L3: y (signal from sample) | M3: =IFERROR(VLOOKUP($B$2,Samdat!$A$4:$B$50,2,FALSE),"—") -> — | Q3: y (signal from sample) | R3: =M3 -> —
A4: Signal Quality | B4: =IF(M7<B5,"Not Significant",IF(M3<M1,"Low Signal",IF(M3<M2,"In Range",IF(M3<R2,"In Range",IF(M3<>"—","High Signal","No Signal"))))) -> No Signal | E4: 1 | F4: YP50-2 | G4: =HLOOKUP($B$2,Caldat!$AC$1:$AT$8,ROW(F4),FALSE) -> 389.91667 | H4: =VLOOKUP($B$2,Caldat!G$2:I$36,2,FALSE) -> 0 | L4: m (slope from calib. curve) | M4: =SLOPE(INDIRECT("H"&(MATCH(1,E2:E8,0)+1)&":H"&(MATCH(1,E2:E8,1)+1)&""),INDIRECT("G"&(MATCH(1,E2:E8,0)+1)&":G"&(MATCH(1,E2:E8,1)+1)&"")) -> 0 | Q4: m (slope from calib. curve) | R4: =SLOPE(INDIRECT("H"&(MATCH(2,E2:E8,0)+1)&":H"&(MATCH(2,E2:E8,1)+1)&""),INDIRECT("G"&(MATCH(2,E2:E8,0)+1)&":G"&(MATCH(2,E2:E8,1)+1)&"")) -> 0
A5: Limit of Detection (ppm) | B5: =VLOOKUP(B2,Caldat!$W$2:$Y$38,2,FALSE) -> 15 | D5: Range 2 | E5: 2 | F5: YP50-3 | G5: =HLOOKUP($B$2,Caldat!$AC$1:$AT$8,ROW(F5),FALSE) -> 572.3897 | H5: =VLOOKUP($B$2,Caldat!J$2:L$34,2,FALSE) -> 0 | L5: b (intercept) | M5: =INTERCEPT(INDIRECT("H"&(MATCH(1,E2:E8,0)+1)&":H"&(MATCH(1,E2:E8,1)+1)&""),INDIRECT("G"&(MATCH(1,E2:E8,0)+1)&":G"&(MATCH(1,E2:E8,1)+1)&"")) -> 0 | Q5: b (intercept) | R5: =INTERCEPT(INDIRECT("H"&(MATCH(2,E2:E8,0)+1)&":H"&(MATCH(2,E2:E8,1)+1)&""),INDIRECT("G"&(MATCH(2,E2:E8,0)+1)&":G"&(MATCH(2,E2:E8,1)+1)&"")) -> 0
A6: Std. Dev. (LOD/3) | B6: =ROUND(B5/3,2) -> 5 | E6: 2 | F6: YP50-4 | G6: =HLOOKUP($B$2,Caldat!$AC$1:$AT$8,ROW(F6),FALSE) -> 941.29921 | H6: =VLOOKUP($B$2,Caldat!M$2:O$36,2,FALSE) -> 0 | L6: R2 (fit value) | M6: =RSQ(INDIRECT("H"&(MATCH(1,E2:E8,0)+1)&":H"&(MATCH(1,E2:E8,1)+1)&""),INDIRECT("G"&(MATCH(1,E2:E8,0)+1)&":G"&(MATCH(1,E2:E8,1)+1)&"")) -> #DIV/0! | Q6: R2 (fit value) | R6: =RSQ(INDIRECT("H"&(MATCH(2,E2:E8,0)+1)&":H"&(MATCH(2,E2:E8,1)+1)&""),INDIRECT("G"&(MATCH(2,E2:E8,0)+1)&":G"&(MATCH(2,E2:E8,1)+1)&"")) -> #DIV/0!
E7: 2 | F7: YP50-5 | G7: =HLOOKUP($B$2,Caldat!$AC$1:$AT$8,ROW(F7),FALSE) -> 1295.1764 | H7: =VLOOKUP($B$2,Caldat!P$2:R$32,2,FALSE) -> 0 | L7: x (concentration) | M7: =IFERROR((M3-M5)/M4,"—") -> — | Q7: x (concentration) | R7: =IFERROR((R3-R5)/R4,"—") -> —
E8: 2 | F8: YP50-6 | G8: =HLOOKUP($B$2,Caldat!$AC$1:$AT$8,ROW(F8),FALSE) -> 1659.3394 | H8: =VLOOKUP($B$2,Caldat!S$2:U$29,2,FALSE) -> 0

Sheet V
A1: Element | B1: Vanadium | E1: Range | F1: Sample | G1: =""&$B$2&" ppm" -> V ppm | H1: =""&$B$2&" Signal" -> V Signal | K1: Range 1: | L1: Range Min Signal | M1: {=INDIRECT("H"&(MATCH(1,E2:E8,0)+1)&"")} -> 0 | P1: Range 2: | Q1: Range Min Signal | R1: {=INDIRECT("H"&(MATCH(2,E2:E8,0)+1)&"")} -> 0
B2: V | F2: YP50-0 | G2: =HLOOKUP($B$2,Caldat!$AC$1:$AT$8,ROW(F2),FALSE) -> 0 | H2: =IFERROR(VLOOKUP($B$2,Caldat!A$2:C$38,2,FALSE),0) -> 0 | L2: Range Max Signal | M2: {=INDIRECT("H"&(MATCH(1,E2:E8,1)+1)&"")} -> 0 | Q2: Range Max Signal | R2: {=INDIRECT("H"&(MATCH(2,E2:E8,1)+1)&"")} -> 0
A3: Concentration (ppm) | B3: =IF(M7<B5,"—",IF(M3<M2,M7,IF(M3<R1,((M3-M2)/(R1-M2))*R7+(1-((M3-M2)/(R1-M2)))*M7,R7))) -> — | D3: Range 1 | E3: 1 | F3: YP50-1 | G3: =HLOOKUP($B$2,Caldat!$AC$1:$AT$8,ROW(F3),FALSE) -> 10.07198 | H3: =VLOOKUP($B$2,Caldat!D$2:F$38,2,FALSE) -> 0 | L3: y (signal from sample) | M3: =IFERROR(VLOOKUP($B$2,Samdat!$A$4:$B$50,2,FALSE),"—") -> — | Q3: y (signal from sample) | R3: =M3 -> —
A4: Signal Quality | B4: =IF(M7<B5,"Not Significant",IF(M3<M1,"Low Signal",IF(M3<M2,"In Range",IF(M3<R2,"In Range",IF(M3<>"—","High Signal","No Signal"))))) -> No Signal | E4: 1 | F4: YP50-2 | G4: =HLOOKUP($B$2,Caldat!$AC$1:$AT$8,ROW(F4),FALSE) -> 18.36306 | H4: =VLOOKUP($B$2,Caldat!G$2:I$36,2,FALSE) -> 0 | L4: m (slope from calib. curve) | M4: =SLOPE(INDIRECT("H"&(MATCH(1,E2:E8,0)+1)&":H"&(MATCH(1,E2:E8,1)+1)&""),INDIRECT("G"&(MATCH(1,E2:E8,0)+1)&":G"&(MATCH(1,E2:E8,1)+1)&"")) -> 0 | Q4: m (slope from calib. curve) | R4: =SLOPE(INDIRECT("H"&(MATCH(2,E2:E8,0)+1)&":H"&(MATCH(2,E2:E8,1)+1)&""),INDIRECT("G"&(MATCH(2,E2:E8,0)+1)&":G"&(MATCH(2,E2:E8,1)+1)&"")) -> 0
A5: Limit of Detection (ppm) | B5: =VLOOKUP(B2,Caldat!$W$2:$Y$38,2,FALSE) -> 10 | E5: 1 | F5: YP50-3 | G5: =HLOOKUP($B$2,Caldat!$AC$1:$AT$8,ROW(F5),FALSE) -> 36.61036 | H5: =VLOOKUP($B$2,Caldat!J$2:L$34,2,FALSE) -> 0 | L5: b (intercept) | M5: =INTERCEPT(INDIRECT("H"&(MATCH(1,E2:E8,0)+1)&":H"&(MATCH(1,E2:E8,1)+1)&""),INDIRECT("G"&(MATCH(1,E2:E8,0)+1)&":G"&(MATCH(1,E2:E8,1)+1)&"")) -> 0 | Q5: b (intercept) | R5: =INTERCEPT(INDIRECT("H"&(MATCH(2,E2:E8,0)+1)&":H"&(MATCH(2,E2:E8,1)+1)&""),INDIRECT("G"&(MATCH(2,E2:E8,0)+1)&":G"&(MATCH(2,E2:E8,1)+1)&"")) -> 0
A6: Std. Dev. (LOD/3) | B6: =ROUND(B5/3,2) -> 3.33 | D6: Range 2 | E6: 2 | F6: YP50-4 | G6: =HLOOKUP($B$2,Caldat!$AC$1:$AT$8,ROW(F6),FALSE) -> 73.50131 | H6: =VLOOKUP($B$2,Caldat!M$2:O$36,2,FALSE) -> 0 | L6: R2 (fit value) | M6: =RSQ(INDIRECT("H"&(MATCH(1,E2:E8,0)+1)&":H"&(MATCH(1,E2:E8,1)+1)&""),INDIRECT("G"&(MATCH(1,E2:E8,0)+1)&":G"&(MATCH(1,E2:E8,1)+1)&"")) -> #DIV/0! | Q6: R2 (fit value) | R6: =RSQ(INDIRECT("H"&(MATCH(2,E2:E8,0)+1)&":H"&(MATCH(2,E2:E8,1)+1)&""),INDIRECT("G"&(MATCH(2,E2:E8,0)+1)&":G"&(MATCH(2,E2:E8,1)+1)&"")) -> #DIV/0!
E7: 2 | F7: YP50-5 | G7: =HLOOKUP($B$2,Caldat!$AC$1:$AT$8,ROW(F7),FALSE) -> 108.889 | H7: =VLOOKUP($B$2,Caldat!P$2:R$32,2,FALSE) -> 0 | L7: x (concentration) | M7: =IFERROR((M3-M5)/M4,"—") -> — | Q7: x (concentration) | R7: =IFERROR((R3-R5)/R4,"—") -> —
E8: 2 | F8: YP50-6 | G8: =HLOOKUP($B$2,Caldat!$AC$1:$AT$8,ROW(F8),FALSE) -> 145.3053 | H8: =VLOOKUP($B$2,Caldat!S$2:U$29,2,FALSE) -> 0

Sheet Cr
A1: Element | B1: Chromium | E1: Range | F1: Sample | G1: =""&$B$2&" ppm" -> Cr ppm | H1: =""&$B$2&" Signal" -> Cr Signal | K1: Range 1: | L1: Range Min Signal | M1: {=INDIRECT("H"&(MATCH(1,E2:E8,0)+1)&"")} -> 0 | P1: Range 2: | Q1: Range Min Signal | R1: {=INDIRECT("H"&(MATCH(2,E2:E8,0)+1)&"")} -> 0
B2: Cr | D2: Range 1 | E2: 1 | F2: YP50-0 | G2: =HLOOKUP($B$2,Caldat!$AC$1:$AT$8,ROW(F2),FALSE) -> 6.4965 | H2: =IFERROR(VLOOKUP($B$2,Caldat!A$2:C$38,2,FALSE),0) -> 0 | L2: Range Max Signal | M2: {=INDIRECT("H"&(MATCH(1,E2:E8,1)+1)&"")} -> 0 | Q2: Range Max Signal | R2: {=INDIRECT("H"&(MATCH(2,E2:E8,1)+1)&"")} -> 0
A3: Concentration (ppm) | B3: =IF(M7<B5,"—",IF(M3<M2,M7,IF(M3<R1,((M3-M2)/(R1-M2))*R7+(1-((M3-M2)/(R1-M2)))*M7,R7))) -> — | E3: 1 | F3: YP50-1 | G3: =HLOOKUP($B$2,Caldat!$AC$1:$AT$8,ROW(F3),FALSE) -> 16.56848 | H3: =VLOOKUP($B$2,Caldat!D$2:F$38,2,FALSE) -> 0 | L3: y (signal from sample) | M3: =IFERROR(VLOOKUP($B$2,Samdat!$A$4:$B$50,2,FALSE),"—") -> — | Q3: y (signal from sample) | R3: =M3 -> —
A4: Signal Quality | B4: =IF(M7<B5,"Not Significant",IF(M3<M1,"Low Signal",IF(M3<M2,"In Range",IF(M3<R2,"In Range",IF(M3<>"—","High Signal","No Signal"))))) -> No Signal | E4: 1 | F4: YP50-2 | G4: =HLOOKUP($B$2,Caldat!$AC$1:$AT$8,ROW(F4),FALSE) -> 24.85956 | H4: =VLOOKUP($B$2,Caldat!G$2:I$36,2,FALSE) -> 0 | L4: m (slope from calib. curve) | M4: =SLOPE(INDIRECT("H"&(MATCH(1,E2:E8,0)+1)&":H"&(MATCH(1,E2:E8,1)+1)&""),INDIRECT("G"&(MATCH(1,E2:E8,0)+1)&":G"&(MATCH(1,E2:E8,1)+1)&"")) -> 0 | Q4: m (slope from calib. curve) | R4: =SLOPE(INDIRECT("H"&(MATCH(2,E2:E8,0)+1)&":H"&(MATCH(2,E2:E8,1)+1)&""),INDIRECT("G"&(MATCH(2,E2:E8,0)+1)&":G"&(MATCH(2,E2:E8,1)+1)&"")) -> 0
A5: Limit of Detection (ppm) | B5: =VLOOKUP(B2,Caldat!$W$2:$Y$38,2,FALSE) -> 8 | E5: 1 | F5: YP50-3 | G5: =HLOOKUP($B$2,Caldat!$AC$1:$AT$8,ROW(F5),FALSE) -> 43.10686 | H5: =VLOOKUP($B$2,Caldat!J$2:L$34,2,FALSE) -> 0 | L5: b (intercept) | M5: =INTERCEPT(INDIRECT("H"&(MATCH(1,E2:E8,0)+1)&":H"&(MATCH(1,E2:E8,1)+1)&""),INDIRECT("G"&(MATCH(1,E2:E8,0)+1)&":G"&(MATCH(1,E2:E8,1)+1)&"")) -> 0 | Q5: b (intercept) | R5: =INTERCEPT(INDIRECT("H"&(MATCH(2,E2:E8,0)+1)&":H"&(MATCH(2,E2:E8,1)+1)&""),INDIRECT("G"&(MATCH(2,E2:E8,0)+1)&":G"&(MATCH(2,E2:E8,1)+1)&"")) -> 0
A6: Std. Dev. (LOD/3) | B6: =ROUND(B5/3,2) -> 2.67 | D6: Range 2 | E6: 2 | F6: YP50-4 | G6: =HLOOKUP($B$2,Caldat!$AC$1:$AT$8,ROW(F6),FALSE) -> 79.99781 | H6: =VLOOKUP($B$2,Caldat!M$2:O$36,2,FALSE) -> 0 | L6: R2 (fit value) | M6: =RSQ(INDIRECT("H"&(MATCH(1,E2:E8,0)+1)&":H"&(MATCH(1,E2:E8,1)+1)&""),INDIRECT("G"&(MATCH(1,E2:E8,0)+1)&":G"&(MATCH(1,E2:E8,1)+1)&"")) -> #DIV/0! | Q6: R2 (fit value) | R6: =RSQ(INDIRECT("H"&(MATCH(2,E2:E8,0)+1)&":H"&(MATCH(2,E2:E8,1)+1)&""),INDIRECT("G"&(MATCH(2,E2:E8,0)+1)&":G"&(MATCH(2,E2:E8,1)+1)&"")) -> #DIV/0!
E7: 2 | F7: YP50-5 | G7: =HLOOKUP($B$2,Caldat!$AC$1:$AT$8,ROW(F7),FALSE) -> 115.3855 | H7: =VLOOKUP($B$2,Caldat!P$2:R$32,2,FALSE) -> 0 | L7: x (concentration) | M7: =IFERROR((M3-M5)/M4,"—") -> — | Q7: x (concentration) | R7: =IFERROR((R3-R5)/R4,"—") -> —
E8: 2 | F8: YP50-6 | G8: =HLOOKUP($B$2,Caldat!$AC$1:$AT$8,ROW(F8),FALSE) -> 151.8018 | H8: =VLOOKUP($B$2,Caldat!S$2:U$29,2,FALSE) -> 0

Sheet Mn
A1: Element | B1: Manganese | E1: Range | F1: Sample | G1: =""&$B$2&" ppm" -> Mn ppm | H1: =""&$B$2&" Signal" -> Mn Signal | K1: Range 1: | L1: Range Min Signal | M1: {=INDIRECT("H"&(MATCH(1,E2:E8,0)+1)&"")} -> 0 | P1: Range 2: | Q1: Range Min Signal | R1: {=INDIRECT("H"&(MATCH(2,E2:E8,0)+1)&"")} -> 0
B2: Mn | F2: YP50-0 | G2: =HLOOKUP($B$2,Caldat!$AC$1:$AT$8,ROW(F2),FALSE) -> 0 | H2: =IFERROR(VLOOKUP($B$2,Caldat!A$2:C$38,2,FALSE),0) -> 0 | L2: Range Max Signal | M2: {=INDIRECT("H"&(MATCH(1,E2:E8,1)+1)&"")} -> 0 | Q2: Range Max Signal | R2: {=INDIRECT("H"&(MATCH(2,E2:E8,1)+1)&"")} -> 0
A3: Concentration (ppm) | B3: =IF(M7<B5,"—",IF(M3<M2,M7,IF(M3<R1,((M3-M2)/(R1-M2))*R7+(1-((M3-M2)/(R1-M2)))*M7,R7))) -> — | D3: Range 1 | E3: 1 | F3: YP50-1 | G3: =HLOOKUP($B$2,Caldat!$AC$1:$AT$8,ROW(F3),FALSE) -> 10.07198 | H3: =VLOOKUP($B$2,Caldat!D$2:F$38,2,FALSE) -> 0 | L3: y (signal from sample) | M3: =IFERROR(VLOOKUP($B$2,Samdat!$A$4:$B$50,2,FALSE),"—") -> — | Q3: y (signal from sample) | R3: =M3 -> —
A4: Signal Quality | B4: =IF(M7<B5,"Not Significant",IF(M3<M1,"Low Signal",IF(M3<M2,"In Range",IF(M3<R2,"In Range",IF(M3<>"—","High Signal","No Signal"))))) -> No Signal | E4: 1 | F4: YP50-2 | G4: =HLOOKUP($B$2,Caldat!$AC$1:$AT$8,ROW(F4),FALSE) -> 18.36306 | H4: =VLOOKUP($B$2,Caldat!G$2:I$36,2,FALSE) -> 0 | L4: m (slope from calib. curve) | M4: =SLOPE(INDIRECT("H"&(MATCH(1,E2:E8,0)+1)&":H"&(MATCH(1,E2:E8,1)+1)&""),INDIRECT("G"&(MATCH(1,E2:E8,0)+1)&":G"&(MATCH(1,E2:E8,1)+1)&"")) -> 0 | Q4: m (slope from calib. curve) | R4: =SLOPE(INDIRECT("H"&(MATCH(2,E2:E8,0)+1)&":H"&(MATCH(2,E2:E8,1)+1)&""),INDIRECT("G"&(MATCH(2,E2:E8,0)+1)&":G"&(MATCH(2,E2:E8,1)+1)&"")) -> 0
A5: Limit of Detection (ppm) | B5: =VLOOKUP(B2,Caldat!$W$2:$Y$38,2,FALSE) -> 6 | E5: 1 | F5: YP50-3 | G5: =HLOOKUP($B$2,Caldat!$AC$1:$AT$8,ROW(F5),FALSE) -> 36.61036 | H5: =VLOOKUP($B$2,Caldat!J$2:L$34,2,FALSE) -> 0 | L5: b (intercept) | M5: =INTERCEPT(INDIRECT("H"&(MATCH(1,E2:E8,0)+1)&":H"&(MATCH(1,E2:E8,1)+1)&""),INDIRECT("G"&(MATCH(1,E2:E8,0)+1)&":G"&(MATCH(1,E2:E8,1)+1)&"")) -> 0 | Q5: b (intercept) | R5: =INTERCEPT(INDIRECT("H"&(MATCH(2,E2:E8,0)+1)&":H"&(MATCH(2,E2:E8,1)+1)&""),INDIRECT("G"&(MATCH(2,E2:E8,0)+1)&":G"&(MATCH(2,E2:E8,1)+1)&"")) -> 0
A6: Std. Dev. (LOD/3) | B6: =ROUND(B5/3,2) -> 2 | D6: Range 2 | E6: 2 | F6: YP50-4 | G6: =HLOOKUP($B$2,Caldat!$AC$1:$AT$8,ROW(F6),FALSE) -> 73.50131 | H6: =VLOOKUP($B$2,Caldat!M$2:O$36,2,FALSE) -> 0 | L6: R2 (fit value) | M6: =RSQ(INDIRECT("H"&(MATCH(1,E2:E8,0)+1)&":H"&(MATCH(1,E2:E8,1)+1)&""),INDIRECT("G"&(MATCH(1,E2:E8,0)+1)&":G"&(MATCH(1,E2:E8,1)+1)&"")) -> #DIV/0! | Q6: R2 (fit value) | R6: =RSQ(INDIRECT("H"&(MATCH(2,E2:E8,0)+1)&":H"&(MATCH(2,E2:E8,1)+1)&""),INDIRECT("G"&(MATCH(2,E2:E8,0)+1)&":G"&(MATCH(2,E2:E8,1)+1)&"")) -> #DIV/0!
E7: 2 | F7: YP50-5 | G7: =HLOOKUP($B$2,Caldat!$AC$1:$AT$8,ROW(F7),FALSE) -> 108.889 | H7: =VLOOKUP($B$2,Caldat!P$2:R$32,2,FALSE) -> 0 | L7: x (concentration) | M7: =IFERROR((M3-M5)/M4,"—") -> — | Q7: x (concentration) | R7: =IFERROR((R3-R5)/R4,"—") -> —
E8: 2 | F8: YP50-6 | G8: =HLOOKUP($B$2,Caldat!$AC$1:$AT$8,ROW(F8),FALSE) -> 145.3053 | H8: =VLOOKUP($B$2,Caldat!S$2:U$29,2,FALSE) -> 0

Sheet Fe
A1: Element | B1: Iron | E1: Range | F1: Sample | G1: =""&$B$2&" ppm" -> Fe ppm | H1: =""&$B$2&" Signal" -> Fe Signal | K1: Range 1: | L1: Range Min Signal | M1: {=INDIRECT("H"&(MATCH(1,E2:E8,0)+1)&"")} -> 0 | P1: Range 2: | Q1: Range Min Signal | R1: {=INDIRECT("H"&(MATCH(2,E2:E8,0)+1)&"")} -> 0
B2: Fe | D2: Range 1 | E2: 1 | F2: YP50-0 | G2: =HLOOKUP($B$2,Caldat!$AC$1:$AT$8,ROW(F2),FALSE) -> 34.79 | H2: =IFERROR(VLOOKUP($B$2,Caldat!A$2:C$38,2,FALSE),0) -> 0 | L2: Range Max Signal | M2: {=INDIRECT("H"&(MATCH(1,E2:E8,1)+1)&"")} -> 0 | Q2: Range Max Signal | R2: {=INDIRECT("H"&(MATCH(2,E2:E8,1)+1)&"")} -> 0
A3: Concentration (ppm) | B3: =IF(M7<B5,"—",IF(M3<M2,M7,IF(M3<R1,((M3-M2)/(R1-M2))*R7+(1-((M3-M2)/(R1-M2)))*M7,R7))) -> — | E3: 1 | F3: YP50-1 | G3: =HLOOKUP($B$2,Caldat!$AC$1:$AT$8,ROW(F3),FALSE) -> 135.5098 | H3: =VLOOKUP($B$2,Caldat!D$2:F$38,2,FALSE) -> 0 | L3: y (signal from sample) | M3: =IFERROR(VLOOKUP($B$2,Samdat!$A$4:$B$50,2,FALSE),"—") -> — | Q3: y (signal from sample) | R3: =M3 -> —
A4: Signal Quality | B4: =IF(M7<B5,"Not Significant",IF(M3<M1,"Low Signal",IF(M3<M2,"In Range",IF(M3<R2,"In Range",IF(M3<>"—","High Signal","No Signal"))))) -> No Signal | E4: 1 | F4: YP50-2 | G4: =HLOOKUP($B$2,Caldat!$AC$1:$AT$8,ROW(F4),FALSE) -> 218.4206 | H4: =VLOOKUP($B$2,Caldat!G$2:I$36,2,FALSE) -> 0 | L4: m (slope from calib. curve) | M4: =SLOPE(INDIRECT("H"&(MATCH(1,E2:E8,0)+1)&":H"&(MATCH(1,E2:E8,1)+1)&""),INDIRECT("G"&(MATCH(1,E2:E8,0)+1)&":G"&(MATCH(1,E2:E8,1)+1)&"")) -> 0 | Q4: m (slope from calib. curve) | R4: =SLOPE(INDIRECT("H"&(MATCH(2,E2:E8,0)+1)&":H"&(MATCH(2,E2:E8,1)+1)&""),INDIRECT("G"&(MATCH(2,E2:E8,0)+1)&":G"&(MATCH(2,E2:E8,1)+1)&"")) -> 0
A5: Limit of Detection (ppm) | B5: =VLOOKUP(B2,Caldat!$W$2:$Y$38,2,FALSE) -> 5 | E5: 1 | F5: YP50-3 | G5: =HLOOKUP($B$2,Caldat!$AC$1:$AT$8,ROW(F5),FALSE) -> 400.8936 | H5: =VLOOKUP($B$2,Caldat!J$2:L$34,2,FALSE) -> 0 | L5: b (intercept) | M5: =INTERCEPT(INDIRECT("H"&(MATCH(1,E2:E8,0)+1)&":H"&(MATCH(1,E2:E8,1)+1)&""),INDIRECT("G"&(MATCH(1,E2:E8,0)+1)&":G"&(MATCH(1,E2:E8,1)+1)&"")) -> 0 | Q5: b (intercept) | R5: =INTERCEPT(INDIRECT("H"&(MATCH(2,E2:E8,0)+1)&":H"&(MATCH(2,E2:E8,1)+1)&""),INDIRECT("G"&(MATCH(2,E2:E8,0)+1)&":G"&(MATCH(2,E2:E8,1)+1)&"")) -> 0
A6: Std. Dev. (LOD/3) | B6: =ROUND(B5/3,2) -> 1.67 | D6: Range 2 | E6: 2 | F6: YP50-4 | G6: =HLOOKUP($B$2,Caldat!$AC$1:$AT$8,ROW(F6),FALSE) -> 769.8031 | H6: =VLOOKUP($B$2,Caldat!M$2:O$36,2,FALSE) -> 0 | L6: R2 (fit value) | M6: =RSQ(INDIRECT("H"&(MATCH(1,E2:E8,0)+1)&":H"&(MATCH(1,E2:E8,1)+1)&""),INDIRECT("G"&(MATCH(1,E2:E8,0)+1)&":G"&(MATCH(1,E2:E8,1)+1)&"")) -> #DIV/0! | Q6: R2 (fit value) | R6: =RSQ(INDIRECT("H"&(MATCH(2,E2:E8,0)+1)&":H"&(MATCH(2,E2:E8,1)+1)&""),INDIRECT("G"&(MATCH(2,E2:E8,0)+1)&":G"&(MATCH(2,E2:E8,1)+1)&"")) -> #DIV/0!
E7: 2 | F7: YP50-5 | G7: =HLOOKUP($B$2,Caldat!$AC$1:$AT$8,ROW(F7),FALSE) -> 1123.68 | H7: =VLOOKUP($B$2,Caldat!P$2:R$32,2,FALSE) -> 0 | L7: x (concentration) | M7: =IFERROR((M3-M5)/M4,"—") -> — | Q7: x (concentration) | R7: =IFERROR((R3-R5)/R4,"—") -> —
E8: 2 | F8: YP50-6 | G8: =HLOOKUP($B$2,Caldat!$AC$1:$AT$8,ROW(F8),FALSE) -> 1487.843 | H8: =VLOOKUP($B$2,Caldat!S$2:U$29,2,FALSE) -> 0

Sheet Co
A1: Element | B1: Cobalt | E1: Range | F1: Sample | G1: =""&$B$2&" ppm" -> Co ppm | H1: =""&$B$2&" Signal" -> Co Signal | K1: Range 1: | L1: Range Min Signal | M1: {=INDIRECT("H"&(MATCH(1,E2:E8,0)+1)&"")} -> 0 | P1: Range 2: | Q1: Range Min Signal | R1: {=INDIRECT("H"&(MATCH(2,E2:E8,0)+1)&"")} -> 0
B2: Co | F2: YP50-0 | G2: =HLOOKUP($B$2,Caldat!$AC$1:$AT$8,ROW(F2),FALSE) -> 0 | H2: =IFERROR(VLOOKUP($B$2,Caldat!A$2:C$38,2,FALSE),0) -> 0 | L2: Range Max Signal | M2: {=INDIRECT("H"&(MATCH(1,E2:E8,1)+1)&"")} -> 0 | Q2: Range Max Signal | R2: {=INDIRECT("H"&(MATCH(2,E2:E8,1)+1)&"")} -> 0
A3: Concentration (ppm) | B3: =IF(M7<B5,"—",IF(M3<M2,M7,IF(M3<R1,((M3-M2)/(R1-M2))*R7+(1-((M3-M2)/(R1-M2)))*M7,R7))) -> — | D3: Range 1 | E3: 1 | F3: YP50-1 | G3: =HLOOKUP($B$2,Caldat!$AC$1:$AT$8,ROW(F3),FALSE) -> 10.071981 | H3: =VLOOKUP($B$2,Caldat!D$2:F$38,2,FALSE) -> 0 | L3: y (signal from sample) | M3: =IFERROR(VLOOKUP($B$2,Samdat!$A$4:$B$50,2,FALSE),"—") -> — | Q3: y (signal from sample) | R3: =M3 -> —
A4: Signal Quality | B4: =IF(M7<B5,"Not Significant",IF(M3<M1,"Low Signal",IF(M3<M2,"In Range",IF(M3<R2,"In Range",IF(M3<>"—","High Signal","No Signal"))))) -> No Signal | E4: 1 | F4: YP50-2 | G4: =HLOOKUP($B$2,Caldat!$AC$1:$AT$8,ROW(F4),FALSE) -> 18.363056 | H4: =VLOOKUP($B$2,Caldat!G$2:I$36,2,FALSE) -> 0 | L4: m (slope from calib. curve) | M4: =SLOPE(INDIRECT("H"&(MATCH(1,E2:E8,0)+1)&":H"&(MATCH(1,E2:E8,1)+1)&""),INDIRECT("G"&(MATCH(1,E2:E8,0)+1)&":G"&(MATCH(1,E2:E8,1)+1)&"")) -> 0 | Q4: m (slope from calib. curve) | R4: =SLOPE(INDIRECT("H"&(MATCH(2,E2:E8,0)+1)&":H"&(MATCH(2,E2:E8,1)+1)&""),INDIRECT("G"&(MATCH(2,E2:E8,0)+1)&":G"&(MATCH(2,E2:E8,1)+1)&"")) -> 0
A5: Limit of Detection (ppm) | B5: =VLOOKUP(B2,Caldat!$W$2:$Y$38,2,FALSE) -> 5 | E5: 1 | F5: YP50-3 | G5: =HLOOKUP($B$2,Caldat!$AC$1:$AT$8,ROW(F5),FALSE) -> 36.61036 | H5: =VLOOKUP($B$2,Caldat!J$2:L$34,2,FALSE) -> 0 | L5: b (intercept) | M5: =INTERCEPT(INDIRECT("H"&(MATCH(1,E2:E8,0)+1)&":H"&(MATCH(1,E2:E8,1)+1)&""),INDIRECT("G"&(MATCH(1,E2:E8,0)+1)&":G"&(MATCH(1,E2:E8,1)+1)&"")) -> 0 | Q5: b (intercept) | R5: =INTERCEPT(INDIRECT("H"&(MATCH(2,E2:E8,0)+1)&":H"&(MATCH(2,E2:E8,1)+1)&""),INDIRECT("G"&(MATCH(2,E2:E8,0)+1)&":G"&(MATCH(2,E2:E8,1)+1)&"")) -> 0
A6: Std. Dev. (LOD/3) | B6: =ROUND(B5/3,2) -> 1.67 | D6: Range 2 | E6: 2 | F6: YP50-4 | G6: =HLOOKUP($B$2,Caldat!$AC$1:$AT$8,ROW(F6),FALSE) -> 73.501311 | H6: =VLOOKUP($B$2,Caldat!M$2:O$36,2,FALSE) -> 0 | L6: R2 (fit value) | M6: =RSQ(INDIRECT("H"&(MATCH(1,E2:E8,0)+1)&":H"&(MATCH(1,E2:E8,1)+1)&""),INDIRECT("G"&(MATCH(1,E2:E8,0)+1)&":G"&(MATCH(1,E2:E8,1)+1)&"")) -> #DIV/0! | Q6: R2 (fit value) | R6: =RSQ(INDIRECT("H"&(MATCH(2,E2:E8,0)+1)&":H"&(MATCH(2,E2:E8,1)+1)&""),INDIRECT("G"&(MATCH(2,E2:E8,0)+1)&":G"&(MATCH(2,E2:E8,1)+1)&"")) -> #DIV/0!
E7: 2 | F7: YP50-5 | G7: =HLOOKUP($B$2,Caldat!$AC$1:$AT$8,ROW(F7),FALSE) -> 108.88903 | H7: =VLOOKUP($B$2,Caldat!P$2:R$32,2,FALSE) -> 0 | L7: x (concentration) | M7: =IFERROR((M3-M5)/M4,"—") -> — | Q7: x (concentration) | R7: =IFERROR((R3-R5)/R4,"—") -> —
E8: 2 | F8: YP50-6 | G8: =HLOOKUP($B$2,Caldat!$AC$1:$AT$8,ROW(F8),FALSE) -> 145.30533 | H8: =VLOOKUP($B$2,Caldat!S$2:U$29,2,FALSE) -> 0

Sheet Ni
A1: Element | B1: Nickel | E1: Range | F1: Sample | G1: =""&$B$2&" ppm" -> Ni ppm | H1: =""&$B$2&" Signal" -> Ni Signal | K1: Range 1: | L1: Range Min Signal | M1: {=INDIRECT("H"&(MATCH(1,E2:E8,0)+1)&"")} -> 0 | P1: Range 2: | Q1: Range Min Signal | R1: {=INDIRECT("H"&(MATCH(2,E2:E8,0)+1)&"")} -> 0
B2: Ni | F2: YP50-0 | G2: =HLOOKUP($B$2,Caldat!$AC$1:$AT$8,ROW(F2),FALSE) -> 0.461 | H2: =IFERROR(VLOOKUP($B$2,Caldat!A$2:C$38,2,FALSE),0) -> 0 | L2: Range Max Signal | M2: {=INDIRECT("H"&(MATCH(1,E2:E8,1)+1)&"")} -> 0 | Q2: Range Max Signal | R2: {=INDIRECT("H"&(MATCH(2,E2:E8,1)+1)&"")} -> 0
A3: Concentration (ppm) | B3: =IF(M7<B5,"—",IF(M3<M2,M7,IF(M3<R1,((M3-M2)/(R1-M2))*R7+(1-((M3-M2)/(R1-M2)))*M7,R7))) -> — | D3: Range 1 | E3: 1 | F3: YP50-1 | G3: =HLOOKUP($B$2,Caldat!$AC$1:$AT$8,ROW(F3),FALSE) -> 10.53298 | H3: =VLOOKUP($B$2,Caldat!D$2:F$38,2,FALSE) -> 0 | L3: y (signal from sample) | M3: =IFERROR(VLOOKUP($B$2,Samdat!$A$4:$B$50,2,FALSE),"—") -> — | Q3: y (signal from sample) | R3: =M3 -> —
A4: Signal Quality | B4: =IF(M7<B5,"Not Significant",IF(M3<M1,"Low Signal",IF(M3<M2,"In Range",IF(M3<R2,"In Range",IF(M3<>"—","High Signal","No Signal"))))) -> No Signal | E4: 1 | F4: YP50-2 | G4: =HLOOKUP($B$2,Caldat!$AC$1:$AT$8,ROW(F4),FALSE) -> 18.82406 | H4: =VLOOKUP($B$2,Caldat!G$2:I$36,2,FALSE) -> 0 | L4: m (slope from calib. curve) | M4: =SLOPE(INDIRECT("H"&(MATCH(1,E2:E8,0)+1)&":H"&(MATCH(1,E2:E8,1)+1)&""),INDIRECT("G"&(MATCH(1,E2:E8,0)+1)&":G"&(MATCH(1,E2:E8,1)+1)&"")) -> 0 | Q4: m (slope from calib. curve) | R4: =SLOPE(INDIRECT("H"&(MATCH(2,E2:E8,0)+1)&":H"&(MATCH(2,E2:E8,1)+1)&""),INDIRECT("G"&(MATCH(2,E2:E8,0)+1)&":G"&(MATCH(2,E2:E8,1)+1)&"")) -> 0
A5: Limit of Detection (ppm) | B5: =VLOOKUP(B2,Caldat!$W$2:$Y$38,2,FALSE) -> 4 | E5: 1 | F5: YP50-3 | G5: =HLOOKUP($B$2,Caldat!$AC$1:$AT$8,ROW(F5),FALSE) -> 37.07136 | H5: =VLOOKUP($B$2,Caldat!J$2:L$34,2,FALSE) -> 0 | L5: b (intercept) | M5: =INTERCEPT(INDIRECT("H"&(MATCH(1,E2:E8,0)+1)&":H"&(MATCH(1,E2:E8,1)+1)&""),INDIRECT("G"&(MATCH(1,E2:E8,0)+1)&":G"&(MATCH(1,E2:E8,1)+1)&"")) -> 0 | Q5: b (intercept) | R5: =INTERCEPT(INDIRECT("H"&(MATCH(2,E2:E8,0)+1)&":H"&(MATCH(2,E2:E8,1)+1)&""),INDIRECT("G"&(MATCH(2,E2:E8,0)+1)&":G"&(MATCH(2,E2:E8,1)+1)&"")) -> 0
A6: Std. Dev. (LOD/3) | B6: =ROUND(B5/3,2) -> 1.33 | D6: Range 2 | E6: 2 | F6: YP50-4 | G6: =HLOOKUP($B$2,Caldat!$AC$1:$AT$8,ROW(F6),FALSE) -> 73.96231 | H6: =VLOOKUP($B$2,Caldat!M$2:O$36,2,FALSE) -> 0 | L6: R2 (fit value) | M6: =RSQ(INDIRECT("H"&(MATCH(1,E2:E8,0)+1)&":H"&(MATCH(1,E2:E8,1)+1)&""),INDIRECT("G"&(MATCH(1,E2:E8,0)+1)&":G"&(MATCH(1,E2:E8,1)+1)&"")) -> #DIV/0! | Q6: R2 (fit value) | R6: =RSQ(INDIRECT("H"&(MATCH(2,E2:E8,0)+1)&":H"&(MATCH(2,E2:E8,1)+1)&""),INDIRECT("G"&(MATCH(2,E2:E8,0)+1)&":G"&(MATCH(2,E2:E8,1)+1)&"")) -> #DIV/0!
E7: 2 | F7: YP50-5 | G7: =HLOOKUP($B$2,Caldat!$AC$1:$AT$8,ROW(F7),FALSE) -> 109.35 | H7: =VLOOKUP($B$2,Caldat!P$2:R$32,2,FALSE) -> 0 | L7: x (concentration) | M7: =IFERROR((M3-M5)/M4,"—") -> — | Q7: x (concentration) | R7: =IFERROR((R3-R5)/R4,"—") -> —
E8: 2 | F8: YP50-6 | G8: =HLOOKUP($B$2,Caldat!$AC$1:$AT$8,ROW(F8),FALSE) -> 145.7663 | H8: =VLOOKUP($B$2,Caldat!S$2:U$29,2,FALSE) -> 0

Sheet Cu
A1: Element | B1: Copper | E1: Range | F1: Sample | G1: =""&$B$2&" ppm" -> Cu ppm | H1: =""&$B$2&" Signal" -> Cu Signal | K1: Range 1: | L1: Range Min Signal | M1: {=INDIRECT("H"&(MATCH(1,E2:E8,0)+1)&"")} -> 0 | P1: Range 2: | Q1: Range Min Signal | R1: {=INDIRECT("H"&(MATCH(2,E2:E8,0)+1)&"")} -> 0
B2: Cu | D2: Range 1 | E2: 1 | F2: YP50-0 | G2: =HLOOKUP($B$2,Caldat!$AC$1:$AT$8,ROW(F2),FALSE) -> 20.54 | H2: =IFERROR(VLOOKUP($B$2,Caldat!A$2:C$38,2,FALSE),0) -> 0 | L2: Range Max Signal | M2: {=INDIRECT("H"&(MATCH(1,E2:E8,1)+1)&"")} -> 0 | Q2: Range Max Signal | R2: {=INDIRECT("H"&(MATCH(2,E2:E8,1)+1)&"")} -> 0
A3: Concentration (ppm) | B3: =IF(M7<B5,"—",IF(M3<M2,M7,IF(M3<R1,((M3-M2)/(R1-M2))*R7+(1-((M3-M2)/(R1-M2)))*M7,R7))) -> — | E3: 1 | F3: YP50-1 | G3: =HLOOKUP($B$2,Caldat!$AC$1:$AT$8,ROW(F3),FALSE) -> 30.61198 | H3: =VLOOKUP($B$2,Caldat!D$2:F$38,2,FALSE) -> 0 | L3: y (signal from sample) | M3: =IFERROR(VLOOKUP($B$2,Samdat!$A$4:$B$50,2,FALSE),"—") -> — | Q3: y (signal from sample) | R3: =M3 -> —
A4: Signal Quality | B4: =IF(M7<B5,"Not Significant",IF(M3<M1,"Low Signal",IF(M3<M2,"In Range",IF(M3<R2,"In Range",IF(M3<>"—","High Signal","No Signal"))))) -> No Signal | E4: 1 | F4: YP50-2 | G4: =HLOOKUP($B$2,Caldat!$AC$1:$AT$8,ROW(F4),FALSE) -> 38.90306 | H4: =VLOOKUP($B$2,Caldat!G$2:I$36,2,FALSE) -> 0 | L4: m (slope from calib. curve) | M4: =SLOPE(INDIRECT("H"&(MATCH(1,E2:E8,0)+1)&":H"&(MATCH(1,E2:E8,1)+1)&""),INDIRECT("G"&(MATCH(1,E2:E8,0)+1)&":G"&(MATCH(1,E2:E8,1)+1)&"")) -> 0 | Q4: m (slope from calib. curve) | R4: =SLOPE(INDIRECT("H"&(MATCH(2,E2:E8,0)+1)&":H"&(MATCH(2,E2:E8,1)+1)&""),INDIRECT("G"&(MATCH(2,E2:E8,0)+1)&":G"&(MATCH(2,E2:E8,1)+1)&"")) -> 0
A5: Limit of Detection (ppm) | B5: =VLOOKUP(B2,Caldat!$W$2:$Y$38,2,FALSE) -> 4 | D5: Range 2 | E5: 2 | F5: YP50-3 | G5: =HLOOKUP($B$2,Caldat!$AC$1:$AT$8,ROW(F5),FALSE) -> 57.15036 | H5: =VLOOKUP($B$2,Caldat!J$2:L$34,2,FALSE) -> 0 | L5: b (intercept) | M5: =INTERCEPT(INDIRECT("H"&(MATCH(1,E2:E8,0)+1)&":H"&(MATCH(1,E2:E8,1)+1)&""),INDIRECT("G"&(MATCH(1,E2:E8,0)+1)&":G"&(MATCH(1,E2:E8,1)+1)&"")) -> 0 | Q5: b (intercept) | R5: =INTERCEPT(INDIRECT("H"&(MATCH(2,E2:E8,0)+1)&":H"&(MATCH(2,E2:E8,1)+1)&""),INDIRECT("G"&(MATCH(2,E2:E8,0)+1)&":G"&(MATCH(2,E2:E8,1)+1)&"")) -> 0
A6: Std. Dev. (LOD/3) | B6: =ROUND(B5/3,2) -> 1.33 | E6: 2 | F6: YP50-4 | G6: =HLOOKUP($B$2,Caldat!$AC$1:$AT$8,ROW(F6),FALSE) -> 94.04131 | H6: =VLOOKUP($B$2,Caldat!M$2:O$36,2,FALSE) -> 0 | L6: R2 (fit value) | M6: =RSQ(INDIRECT("H"&(MATCH(1,E2:E8,0)+1)&":H"&(MATCH(1,E2:E8,1)+1)&""),INDIRECT("G"&(MATCH(1,E2:E8,0)+1)&":G"&(MATCH(1,E2:E8,1)+1)&"")) -> #DIV/0! | Q6: R2 (fit value) | R6: =RSQ(INDIRECT("H"&(MATCH(2,E2:E8,0)+1)&":H"&(MATCH(2,E2:E8,1)+1)&""),INDIRECT("G"&(MATCH(2,E2:E8,0)+1)&":G"&(MATCH(2,E2:E8,1)+1)&"")) -> #DIV/0!
E7: 2 | F7: YP50-5 | G7: =HLOOKUP($B$2,Caldat!$AC$1:$AT$8,ROW(F7),FALSE) -> 129.429 | H7: =VLOOKUP($B$2,Caldat!P$2:R$32,2,FALSE) -> 0 | L7: x (concentration) | M7: =IFERROR((M3-M5)/M4,"—") -> — | Q7: x (concentration) | R7: =IFERROR((R3-R5)/R4,"—") -> —
E8: 2 | F8: YP50-6 | G8: =HLOOKUP($B$2,Caldat!$AC$1:$AT$8,ROW(F8),FALSE) -> 165.8453 | H8: =VLOOKUP($B$2,Caldat!S$2:U$29,2,FALSE) -> 0

Sheet Zn
A1: Element | B1: Zinc | E1: Range | F1: Sample | G1: =""&$B$2&" ppm" -> Zn ppm | H1: =""&$B$2&" Signal" -> Zn Signal | K1: Range 1: | L1: Range Min Signal | M1: {=INDIRECT("H"&(MATCH(1,E2:E8,0)+1)&"")} -> 0 | P1: Range 2: | Q1: Range Min Signal | R1: {=INDIRECT("H"&(MATCH(2,E2:E8,0)+1)&"")} -> 0
B2: Zn | F2: YP50-0 | G2: =HLOOKUP($B$2,Caldat!$AC$1:$AT$8,ROW(F2),FALSE) -> 0 | H2: =IFERROR(VLOOKUP($B$2,Caldat!A$2:C$38,2,FALSE),0) -> 0 | L2: Range Max Signal | M2: {=INDIRECT("H"&(MATCH(1,E2:E8,1)+1)&"")} -> 0 | Q2: Range Max Signal | R2: {=INDIRECT("H"&(MATCH(2,E2:E8,1)+1)&"")} -> 0
A3: Concentration (ppm) | B3: =IF(M7<B5,"—",IF(M3<M2,M7,IF(M3<R1,((M3-M2)/(R1-M2))*R7+(1-((M3-M2)/(R1-M2)))*M7,R7))) -> — | D3: Range 1 | E3: 1 | F3: YP50-1 | G3: =HLOOKUP($B$2,Caldat!$AC$1:$AT$8,ROW(F3),FALSE) -> 10.07198 | H3: =VLOOKUP($B$2,Caldat!D$2:F$38,2,FALSE) -> 0 | L3: y (signal from sample) | M3: =IFERROR(VLOOKUP($B$2,Samdat!$A$4:$B$50,2,FALSE),"—") -> — | Q3: y (signal from sample) | R3: =M3 -> —
A4: Signal Quality | B4: =IF(M7<B5,"Not Significant",IF(M3<M1,"Low Signal",IF(M3<M2,"In Range",IF(M3<R2,"In Range",IF(M3<>"—","High Signal","No Signal"))))) -> No Signal | E4: 1 | F4: YP50-2 | G4: =HLOOKUP($B$2,Caldat!$AC$1:$AT$8,ROW(F4),FALSE) -> 18.36306 | H4: =VLOOKUP($B$2,Caldat!G$2:I$36,2,FALSE) -> 0 | L4: m (slope from calib. curve) | M4: =SLOPE(INDIRECT("H"&(MATCH(1,E2:E8,0)+1)&":H"&(MATCH(1,E2:E8,1)+1)&""),INDIRECT("G"&(MATCH(1,E2:E8,0)+1)&":G"&(MATCH(1,E2:E8,1)+1)&"")) -> 0 | Q4: m (slope from calib. curve) | R4: =SLOPE(INDIRECT("H"&(MATCH(2,E2:E8,0)+1)&":H"&(MATCH(2,E2:E8,1)+1)&""),INDIRECT("G"&(MATCH(2,E2:E8,0)+1)&":G"&(MATCH(2,E2:E8,1)+1)&"")) -> 0
A5: Limit of Detection (ppm) | B5: =VLOOKUP(B2,Caldat!$W$2:$Y$38,2,FALSE) -> 5 | E5: 1 | F5: YP50-3 | G5: =HLOOKUP($B$2,Caldat!$AC$1:$AT$8,ROW(F5),FALSE) -> 36.61036 | H5: =VLOOKUP($B$2,Caldat!J$2:L$34,2,FALSE) -> 0 | L5: b (intercept) | M5: =INTERCEPT(INDIRECT("H"&(MATCH(1,E2:E8,0)+1)&":H"&(MATCH(1,E2:E8,1)+1)&""),INDIRECT("G"&(MATCH(1,E2:E8,0)+1)&":G"&(MATCH(1,E2:E8,1)+1)&"")) -> 0 | Q5: b (intercept) | R5: =INTERCEPT(INDIRECT("H"&(MATCH(2,E2:E8,0)+1)&":H"&(MATCH(2,E2:E8,1)+1)&""),INDIRECT("G"&(MATCH(2,E2:E8,0)+1)&":G"&(MATCH(2,E2:E8,1)+1)&"")) -> 0
A6: Std. Dev. (LOD/3) | B6: =ROUND(B5/3,2) -> 1.67 | D6: Range 2 | E6: 2 | F6: YP50-4 | G6: =HLOOKUP($B$2,Caldat!$AC$1:$AT$8,ROW(F6),FALSE) -> 73.50131 | H6: =VLOOKUP($B$2,Caldat!M$2:O$36,2,FALSE) -> 0 | L6: R2 (fit value) | M6: =RSQ(INDIRECT("H"&(MATCH(1,E2:E8,0)+1)&":H"&(MATCH(1,E2:E8,1)+1)&""),INDIRECT("G"&(MATCH(1,E2:E8,0)+1)&":G"&(MATCH(1,E2:E8,1)+1)&"")) -> #DIV/0! | Q6: R2 (fit value) | R6: =RSQ(INDIRECT("H"&(MATCH(2,E2:E8,0)+1)&":H"&(MATCH(2,E2:E8,1)+1)&""),INDIRECT("G"&(MATCH(2,E2:E8,0)+1)&":G"&(MATCH(2,E2:E8,1)+1)&"")) -> #DIV/0!
E7: 2 | F7: YP50-5 | G7: =HLOOKUP($B$2,Caldat!$AC$1:$AT$8,ROW(F7),FALSE) -> 108.889 | H7: =VLOOKUP($B$2,Caldat!P$2:R$32,2,FALSE) -> 0 | L7: x (concentration) | M7: =IFERROR((M3-M5)/M4,"—") -> — | Q7: x (concentration) | R7: =IFERROR((R3-R5)/R4,"—") -> —
E8: 2 | F8: YP50-6 | G8: =HLOOKUP($B$2,Caldat!$AC$1:$AT$8,ROW(F8),FALSE) -> 145.3053 | H8: =VLOOKUP($B$2,Caldat!S$2:U$29,2,FALSE) -> 0

Sheet Ga
A1: Element | B1: Gallium | E1: Range | F1: Sample | G1: =""&$B$2&" ppm" -> Ga ppm | H1: =""&$B$2&" Signal" -> Ga Signal | K1: Range 1: | L1: Range Min Signal | M1: {=INDIRECT("H"&(MATCH(1,E2:E8,0)+1)&"")} -> 0 | P1: Range 2: | Q1: Range Min Signal | R1: {=INDIRECT("H"&(MATCH(2,E2:E8,0)+1)&"")} -> 0
B2: Ga | F2: YP50-0 | G2: =HLOOKUP($B$2,Caldat!$AC$1:$AT$8,ROW(F2),FALSE) -> 0 | H2: =IFERROR(VLOOKUP($B$2,Caldat!A$2:C$38,2,FALSE),0) -> 0 | L2: Range Max Signal | M2: {=INDIRECT("H"&(MATCH(1,E2:E8,1)+1)&"")} -> 0 | Q2: Range Max Signal | R2: {=INDIRECT("H"&(MATCH(2,E2:E8,1)+1)&"")} -> 0
A3: Concentration (ppm) | B3: =IF(M7<B5,"—",IF(M3<M2,M7,IF(M3<R1,((M3-M2)/(R1-M2))*R7+(1-((M3-M2)/(R1-M2)))*M7,R7))) -> — | D3: Range 1 | E3: 1 | F3: YP50-1 | G3: =HLOOKUP($B$2,Caldat!$AC$1:$AT$8,ROW(F3),FALSE) -> 10.07198 | H3: =VLOOKUP($B$2,Caldat!D$2:F$38,2,FALSE) -> 0 | L3: y (signal from sample) | M3: =IFERROR(VLOOKUP($B$2,Samdat!$A$4:$B$50,2,FALSE),"—") -> — | Q3: y (signal from sample) | R3: =M3 -> —
A4: Signal Quality | B4: =IF(M7<B5,"Not Significant",IF(M3<M1,"Low Signal",IF(M3<M2,"In Range",IF(M3<R2,"In Range",IF(M3<>"—","High Signal","No Signal"))))) -> No Signal | E4: 1 | F4: YP50-2 | G4: =HLOOKUP($B$2,Caldat!$AC$1:$AT$8,ROW(F4),FALSE) -> 18.36306 | H4: =VLOOKUP($B$2,Caldat!G$2:I$36,2,FALSE) -> 0 | L4: m (slope from calib. curve) | M4: =SLOPE(INDIRECT("H"&(MATCH(1,E2:E8,0)+1)&":H"&(MATCH(1,E2:E8,1)+1)&""),INDIRECT("G"&(MATCH(1,E2:E8,0)+1)&":G"&(MATCH(1,E2:E8,1)+1)&"")) -> 0 | Q4: m (slope from calib. curve) | R4: =SLOPE(INDIRECT("H"&(MATCH(2,E2:E8,0)+1)&":H"&(MATCH(2,E2:E8,1)+1)&""),INDIRECT("G"&(MATCH(2,E2:E8,0)+1)&":G"&(MATCH(2,E2:E8,1)+1)&"")) -> 0
A5: Limit of Detection (ppm) | B5: =VLOOKUP(B2,Caldat!$W$2:$Y$38,2,FALSE) -> 5 | E5: 1 | F5: YP50-3 | G5: =HLOOKUP($B$2,Caldat!$AC$1:$AT$8,ROW(F5),FALSE) -> 36.61036 | H5: =VLOOKUP($B$2,Caldat!J$2:L$34,2,FALSE) -> 0 | L5: b (intercept) | M5: =INTERCEPT(INDIRECT("H"&(MATCH(1,E2:E8,0)+1)&":H"&(MATCH(1,E2:E8,1)+1)&""),INDIRECT("G"&(MATCH(1,E2:E8,0)+1)&":G"&(MATCH(1,E2:E8,1)+1)&"")) -> 0 | Q5: b (intercept) | R5: =INTERCEPT(INDIRECT("H"&(MATCH(2,E2:E8,0)+1)&":H"&(MATCH(2,E2:E8,1)+1)&""),INDIRECT("G"&(MATCH(2,E2:E8,0)+1)&":G"&(MATCH(2,E2:E8,1)+1)&"")) -> 0
A6: Std. Dev. (LOD/3) | B6: =ROUND(B5/3,2) -> 1.67 | D6: Range 2 | E6: 2 | F6: YP50-4 | G6: =HLOOKUP($B$2,Caldat!$AC$1:$AT$8,ROW(F6),FALSE) -> 73.50131 | H6: =VLOOKUP($B$2,Caldat!M$2:O$36,2,FALSE) -> 0 | L6: R2 (fit value) | M6: =RSQ(INDIRECT("H"&(MATCH(1,E2:E8,0)+1)&":H"&(MATCH(1,E2:E8,1)+1)&""),INDIRECT("G"&(MATCH(1,E2:E8,0)+1)&":G"&(MATCH(1,E2:E8,1)+1)&"")) -> #DIV/0! | Q6: R2 (fit value) | R6: =RSQ(INDIRECT("H"&(MATCH(2,E2:E8,0)+1)&":H"&(MATCH(2,E2:E8,1)+1)&""),INDIRECT("G"&(MATCH(2,E2:E8,0)+1)&":G"&(MATCH(2,E2:E8,1)+1)&"")) -> #DIV/0!
E7: 2 | F7: YP50-5 | G7: =HLOOKUP($B$2,Caldat!$AC$1:$AT$8,ROW(F7),FALSE) -> 108.889 | H7: =VLOOKUP($B$2,Caldat!P$2:R$32,2,FALSE) -> 0 | L7: x (concentration) | M7: =IFERROR((M3-M5)/M4,"—") -> — | Q7: x (concentration) | R7: =IFERROR((R3-R5)/R4,"—") -> —
E8: 2 | F8: YP50-6 | G8: =HLOOKUP($B$2,Caldat!$AC$1:$AT$8,ROW(F8),FALSE) -> 145.3053 | H8: =VLOOKUP($B$2,Caldat!S$2:U$29,2,FALSE) -> 0

Sheet Rb
A1: Element | B1: Rubidium | E1: Range | F1: Sample | G1: =""&$B$2&" ppm" -> Rb ppm | H1: =""&$B$2&" Signal" -> Rb Signal | K1: Range 1: | L1: Range Min Signal | M1: {=INDIRECT("H"&(MATCH(1,E2:E8,0)+1)&"")} -> 0 | P1: Range 2: | Q1: Range Min Signal | R1: {=INDIRECT("H"&(MATCH(2,E2:E8,0)+1)&"")} -> 0
B2: Rb | F2: YP50-0 | G2: =HLOOKUP($B$2,Caldat!$AC$1:$AT$8,ROW(F2),FALSE) -> 0 | H2: =IFERROR(VLOOKUP($B$2,Caldat!A$2:C$38,2,FALSE),0) -> 0 | L2: Range Max Signal | M2: {=INDIRECT("H"&(MATCH(1,E2:E8,1)+1)&"")} -> 0 | Q2: Range Max Signal | R2: {=INDIRECT("H"&(MATCH(2,E2:E8,1)+1)&"")} -> 0
A3: Concentration (ppm) | B3: =IF(M7<B5,"—",IF(M3<M2,M7,IF(M3<R1,((M3-M2)/(R1-M2))*R7+(1-((M3-M2)/(R1-M2)))*M7,R7))) -> — | D3: Range 1 | E3: 1 | F3: YP50-1 | G3: =HLOOKUP($B$2,Caldat!$AC$1:$AT$8,ROW(F3),FALSE) -> 10.07198 | H3: =VLOOKUP($B$2,Caldat!D$2:F$38,2,FALSE) -> 0 | L3: y (signal from sample) | M3: =IFERROR(VLOOKUP($B$2,Samdat!$A$4:$B$50,2,FALSE),"—") -> — | Q3: y (signal from sample) | R3: =M3 -> —
A4: Signal Quality | B4: =IF(M7<B5,"Not Significant",IF(M3<M1,"Low Signal",IF(M3<M2,"In Range",IF(M3<R2,"In Range",IF(M3<>"—","High Signal","No Signal"))))) -> No Signal | E4: 1 | F4: YP50-2 | G4: =HLOOKUP($B$2,Caldat!$AC$1:$AT$8,ROW(F4),FALSE) -> 18.36306 | H4: =VLOOKUP($B$2,Caldat!G$2:I$36,2,FALSE) -> 0 | L4: m (slope from calib. curve) | M4: =SLOPE(INDIRECT("H"&(MATCH(1,E2:E8,0)+1)&":H"&(MATCH(1,E2:E8,1)+1)&""),INDIRECT("G"&(MATCH(1,E2:E8,0)+1)&":G"&(MATCH(1,E2:E8,1)+1)&"")) -> 0 | Q4: m (slope from calib. curve) | R4: =SLOPE(INDIRECT("H"&(MATCH(2,E2:E8,0)+1)&":H"&(MATCH(2,E2:E8,1)+1)&""),INDIRECT("G"&(MATCH(2,E2:E8,0)+1)&":G"&(MATCH(2,E2:E8,1)+1)&"")) -> 0
A5: Limit of Detection (ppm) | B5: =VLOOKUP(B2,Caldat!$W$2:$Y$38,2,FALSE) -> 4 | E5: 1 | F5: YP50-3 | G5: =HLOOKUP($B$2,Caldat!$AC$1:$AT$8,ROW(F5),FALSE) -> 36.61036 | H5: =VLOOKUP($B$2,Caldat!J$2:L$34,2,FALSE) -> 0 | L5: b (intercept) | M5: =INTERCEPT(INDIRECT("H"&(MATCH(1,E2:E8,0)+1)&":H"&(MATCH(1,E2:E8,1)+1)&""),INDIRECT("G"&(MATCH(1,E2:E8,0)+1)&":G"&(MATCH(1,E2:E8,1)+1)&"")) -> 0 | Q5: b (intercept) | R5: =INTERCEPT(INDIRECT("H"&(MATCH(2,E2:E8,0)+1)&":H"&(MATCH(2,E2:E8,1)+1)&""),INDIRECT("G"&(MATCH(2,E2:E8,0)+1)&":G"&(MATCH(2,E2:E8,1)+1)&"")) -> 0
A6: Std. Dev. (LOD/3) | B6: =ROUND(B5/3,2) -> 1.33 | D6: Range 2 | E6: 2 | F6: YP50-4 | G6: =HLOOKUP($B$2,Caldat!$AC$1:$AT$8,ROW(F6),FALSE) -> 73.50131 | H6: =VLOOKUP($B$2,Caldat!M$2:O$36,2,FALSE) -> 0 | L6: R2 (fit value) | M6: =RSQ(INDIRECT("H"&(MATCH(1,E2:E8,0)+1)&":H"&(MATCH(1,E2:E8,1)+1)&""),INDIRECT("G"&(MATCH(1,E2:E8,0)+1)&":G"&(MATCH(1,E2:E8,1)+1)&"")) -> #DIV/0! | Q6: R2 (fit value) | R6: =RSQ(INDIRECT("H"&(MATCH(2,E2:E8,0)+1)&":H"&(MATCH(2,E2:E8,1)+1)&""),INDIRECT("G"&(MATCH(2,E2:E8,0)+1)&":G"&(MATCH(2,E2:E8,1)+1)&"")) -> #DIV/0!
E7: 2 | F7: YP50-5 | G7: =HLOOKUP($B$2,Caldat!$AC$1:$AT$8,ROW(F7),FALSE) -> 108.889 | H7: =VLOOKUP($B$2,Caldat!P$2:R$32,2,FALSE) -> 0 | L7: x (concentration) | M7: =IFERROR((M3-M5)/M4,"—") -> — | Q7: x (concentration) | R7: =IFERROR((R3-R5)/R4,"—") -> —
E8: 2 | F8: YP50-6 | G8: =HLOOKUP($B$2,Caldat!$AC$1:$AT$8,ROW(F8),FALSE) -> 145.3053 | H8: =VLOOKUP($B$2,Caldat!S$2:U$29,2,FALSE) -> 0

Sheet Sr
A1: Element | B1: Strontium | E1: Range | F1: Sample | G1: =""&$B$2&" ppm" -> Sr ppm | H1: =""&$B$2&" Signal" -> Sr Signal | K1: Range 1: | L1: Range Min Signal | M1: {=INDIRECT("H"&(MATCH(1,E2:E8,0)+1)&"")} -> 0 | P1: Range 2: | Q1: Range Min Signal | R1: {=INDIRECT("H"&(MATCH(2,E2:E8,0)+1)&"")} -> 0
B2: Sr | F2: YP50-0 | G2: =HLOOKUP($B$2,Caldat!$AC$1:$AT$8,ROW(F2),FALSE) -> 0 | H2: =IFERROR(VLOOKUP($B$2,Caldat!A$2:C$38,2,FALSE),0) -> 0 | L2: Range Max Signal | M2: {=INDIRECT("H"&(MATCH(1,E2:E8,1)+1)&"")} -> 0 | Q2: Range Max Signal | R2: {=INDIRECT("H"&(MATCH(2,E2:E8,1)+1)&"")} -> 0
A3: Concentration (ppm) | B3: =IF(M7<B5,"—",IF(M3<M2,M7,IF(M3<R1,((M3-M2)/(R1-M2))*R7+(1-((M3-M2)/(R1-M2)))*M7,R7))) -> — | D3: Range 1 | E3: 1 | F3: YP50-1 | G3: =HLOOKUP($B$2,Caldat!$AC$1:$AT$8,ROW(F3),FALSE) -> 10.07198 | H3: =VLOOKUP($B$2,Caldat!D$2:F$38,2,FALSE) -> 0 | L3: y (signal from sample) | M3: =IFERROR(VLOOKUP($B$2,Samdat!$A$4:$B$50,2,FALSE),"—") -> — | Q3: y (signal from sample) | R3: =M3 -> —
A4: Signal Quality | B4: =IF(M7<B5,"Not Significant",IF(M3<M1,"Low Signal",IF(M3<M2,"In Range",IF(M3<R2,"In Range",IF(M3<>"—","High Signal","No Signal"))))) -> No Signal | E4: 1 | F4: YP50-2 | G4: =HLOOKUP($B$2,Caldat!$AC$1:$AT$8,ROW(F4),FALSE) -> 18.36306 | H4: =VLOOKUP($B$2,Caldat!G$2:I$36,2,FALSE) -> 0 | L4: m (slope from calib. curve) | M4: =SLOPE(INDIRECT("H"&(MATCH(1,E2:E8,0)+1)&":H"&(MATCH(1,E2:E8,1)+1)&""),INDIRECT("G"&(MATCH(1,E2:E8,0)+1)&":G"&(MATCH(1,E2:E8,1)+1)&"")) -> 0 | Q4: m (slope from calib. curve) | R4: =SLOPE(INDIRECT("H"&(MATCH(2,E2:E8,0)+1)&":H"&(MATCH(2,E2:E8,1)+1)&""),INDIRECT("G"&(MATCH(2,E2:E8,0)+1)&":G"&(MATCH(2,E2:E8,1)+1)&"")) -> 0
A5: Limit of Detection (ppm) | B5: =VLOOKUP(B2,Caldat!$W$2:$Y$38,2,FALSE) -> 3 | E5: 1 | F5: YP50-3 | G5: =HLOOKUP($B$2,Caldat!$AC$1:$AT$8,ROW(F5),FALSE) -> 36.61036 | H5: =VLOOKUP($B$2,Caldat!J$2:L$34,2,FALSE) -> 0 | L5: b (intercept) | M5: =INTERCEPT(INDIRECT("H"&(MATCH(1,E2:E8,0)+1)&":H"&(MATCH(1,E2:E8,1)+1)&""),INDIRECT("G"&(MATCH(1,E2:E8,0)+1)&":G"&(MATCH(1,E2:E8,1)+1)&"")) -> 0 | Q5: b (intercept) | R5: =INTERCEPT(INDIRECT("H"&(MATCH(2,E2:E8,0)+1)&":H"&(MATCH(2,E2:E8,1)+1)&""),INDIRECT("G"&(MATCH(2,E2:E8,0)+1)&":G"&(MATCH(2,E2:E8,1)+1)&"")) -> 0
A6: Std. Dev. (LOD/3) | B6: =ROUND(B5/3,2) -> 1 | D6: Range 2 | E6: 2 | F6: YP50-4 | G6: =HLOOKUP($B$2,Caldat!$AC$1:$AT$8,ROW(F6),FALSE) -> 73.50131 | H6: =VLOOKUP($B$2,Caldat!M$2:O$36,2,FALSE) -> 0 | L6: R2 (fit value) | M6: =RSQ(INDIRECT("H"&(MATCH(1,E2:E8,0)+1)&":H"&(MATCH(1,E2:E8,1)+1)&""),INDIRECT("G"&(MATCH(1,E2:E8,0)+1)&":G"&(MATCH(1,E2:E8,1)+1)&"")) -> #DIV/0! | Q6: R2 (fit value) | R6: =RSQ(INDIRECT("H"&(MATCH(2,E2:E8,0)+1)&":H"&(MATCH(2,E2:E8,1)+1)&""),INDIRECT("G"&(MATCH(2,E2:E8,0)+1)&":G"&(MATCH(2,E2:E8,1)+1)&"")) -> #DIV/0!
E7: 2 | F7: YP50-5 | G7: =HLOOKUP($B$2,Caldat!$AC$1:$AT$8,ROW(F7),FALSE) -> 108.889 | H7: =VLOOKUP($B$2,Caldat!P$2:R$32,2,FALSE) -> 0 | L7: x (concentration) | M7: =IFERROR((M3-M5)/M4,"—") -> — | Q7: x (concentration) | R7: =IFERROR((R3-R5)/R4,"—") -> —
E8: 2 | F8: YP50-6 | G8: =HLOOKUP($B$2,Caldat!$AC$1:$AT$8,ROW(F8),FALSE) -> 145.3053 | H8: =VLOOKUP($B$2,Caldat!S$2:U$29,2,FALSE) -> 0

Sheet Mo
A1: Element | B1: Molybdenum | E1: Range | F1: Sample | G1: =""&$B$2&" ppm" -> Mo ppm | H1: =""&$B$2&" Signal" -> Mo Signal | K1: Range 1: | L1: Range Min Signal | M1: {=INDIRECT("H"&(MATCH(1,E2:E8,0)+1)&"")} -> 0 | P1: Range 2: | Q1: Range Min Signal | R1: {=INDIRECT("H"&(MATCH(2,E2:E8,0)+1)&"")} -> 0
B2: Mo | F2: YP50-0 | G2: =HLOOKUP($B$2,Caldat!$AC$1:$AT$8,ROW(F2),FALSE) -> 0 | H2: =IFERROR(VLOOKUP($B$2,Caldat!A$2:C$38,2,FALSE),0) -> 0 | L2: Range Max Signal | M2: {=INDIRECT("H"&(MATCH(1,E2:E8,1)+1)&"")} -> 0 | Q2: Range Max Signal | R2: {=INDIRECT("H"&(MATCH(2,E2:E8,1)+1)&"")} -> 0
A3: Concentration (ppm) | B3: =IF(M7<B5,"—",IF(M3<M2,M7,IF(M3<R1,((M3-M2)/(R1-M2))*R7+(1-((M3-M2)/(R1-M2)))*M7,R7))) -> — | D3: Range 1 | E3: 1 | F3: YP50-1 | G3: =HLOOKUP($B$2,Caldat!$AC$1:$AT$8,ROW(F3),FALSE) -> 10.07198 | H3: =IFERROR(VLOOKUP($B$2,Caldat!D$2:F$38,2,FALSE),0) -> 0 | L3: y (signal from sample) | M3: =IFERROR(VLOOKUP($B$2,Samdat!$A$4:$B$50,2,FALSE),"—") -> — | Q3: y (signal from sample) | R3: =M3 -> —
A4: Signal Quality | B4: =IF(M7<B5,"Not Significant",IF(M3<M1,"Low Signal",IF(M3<M2,"In Range",IF(M3<R2,"In Range",IF(M3<>"—","High Signal","No Signal"))))) -> No Signal | E4: 1 | F4: YP50-2 | G4: =HLOOKUP($B$2,Caldat!$AC$1:$AT$8,ROW(F4),FALSE) -> 18.36306 | H4: =VLOOKUP($B$2,Caldat!G$2:I$36,2,FALSE) -> 0 | L4: m (slope from calib. curve) | M4: =SLOPE(INDIRECT("H"&(MATCH(1,E2:E8,0)+1)&":H"&(MATCH(1,E2:E8,1)+1)&""),INDIRECT("G"&(MATCH(1,E2:E8,0)+1)&":G"&(MATCH(1,E2:E8,1)+1)&"")) -> 0 | Q4: m (slope from calib. curve) | R4: =SLOPE(INDIRECT("H"&(MATCH(2,E2:E8,0)+1)&":H"&(MATCH(2,E2:E8,1)+1)&""),INDIRECT("G"&(MATCH(2,E2:E8,0)+1)&":G"&(MATCH(2,E2:E8,1)+1)&"")) -> 0
A5: Limit of Detection (ppm) | B5: =VLOOKUP(B2,Caldat!$W$2:$Y$38,2,FALSE) -> 3 | E5: 1 | F5: YP50-3 | G5: =HLOOKUP($B$2,Caldat!$AC$1:$AT$8,ROW(F5),FALSE) -> 36.61036 | H5: =VLOOKUP($B$2,Caldat!J$2:L$34,2,FALSE) -> 0 | L5: b (intercept) | M5: =INTERCEPT(INDIRECT("H"&(MATCH(1,E2:E8,0)+1)&":H"&(MATCH(1,E2:E8,1)+1)&""),INDIRECT("G"&(MATCH(1,E2:E8,0)+1)&":G"&(MATCH(1,E2:E8,1)+1)&"")) -> 0 | Q5: b (intercept) | R5: =INTERCEPT(INDIRECT("H"&(MATCH(2,E2:E8,0)+1)&":H"&(MATCH(2,E2:E8,1)+1)&""),INDIRECT("G"&(MATCH(2,E2:E8,0)+1)&":G"&(MATCH(2,E2:E8,1)+1)&"")) -> 0
A6: Std. Dev. (LOD/3) | B6: =ROUND(B5/3,2) -> 1 | D6: Range 2 | E6: 2 | F6: YP50-4 | G6: =HLOOKUP($B$2,Caldat!$AC$1:$AT$8,ROW(F6),FALSE) -> 73.50131 | H6: =VLOOKUP($B$2,Caldat!M$2:O$36,2,FALSE) -> 0 | L6: R2 (fit value) | M6: =RSQ(INDIRECT("H"&(MATCH(1,E2:E8,0)+1)&":H"&(MATCH(1,E2:E8,1)+1)&""),INDIRECT("G"&(MATCH(1,E2:E8,0)+1)&":G"&(MATCH(1,E2:E8,1)+1)&"")) -> #DIV/0! | Q6: R2 (fit value) | R6: =RSQ(INDIRECT("H"&(MATCH(2,E2:E8,0)+1)&":H"&(MATCH(2,E2:E8,1)+1)&""),INDIRECT("G"&(MATCH(2,E2:E8,0)+1)&":G"&(MATCH(2,E2:E8,1)+1)&"")) -> #DIV/0!
E7: 2 | F7: YP50-5 | G7: =HLOOKUP($B$2,Caldat!$AC$1:$AT$8,ROW(F7),FALSE) -> 108.889 | H7: =VLOOKUP($B$2,Caldat!P$2:R$32,2,FALSE) -> 0 | L7: x (concentration) | M7: =IFERROR((M3-M5)/M4,"—") -> — | Q7: x (concentration) | R7: =IFERROR((R3-R5)/R4,"—") -> —
E8: 2 | F8: YP50-6 | G8: =HLOOKUP($B$2,Caldat!$AC$1:$AT$8,ROW(F8),FALSE) -> 145.3053 | H8: =VLOOKUP($B$2,Caldat!S$2:U$29,2,FALSE) -> 0

Sheet Cd
